{
 "cells": [
  {
   "cell_type": "code",
   "execution_count": 26,
   "metadata": {},
   "outputs": [],
   "source": [
    "import warnings\n",
    "warnings.filterwarnings('ignore')"
   ]
  },
  {
   "cell_type": "code",
   "execution_count": 27,
   "metadata": {},
   "outputs": [],
   "source": [
    "import numpy as np\n",
    "import pandas as pd\n",
    "import tensorflow as tf\n",
    "from sklearn.model_selection import GridSearchCV, RandomizedSearchCV\n",
    "from keras.models import Sequential\n",
    "from keras.layers import Dense\n",
    "from scikeras.wrappers import KerasClassifier\n",
    "from keras.constraints import MaxNorm"
   ]
  },
  {
   "cell_type": "code",
   "execution_count": 28,
   "metadata": {},
   "outputs": [],
   "source": [
    "# Epoch y Batch Optimization\n",
    "def create_model():\n",
    "    # create model\n",
    "    model = Sequential()\n",
    "    model.add(Dense(32, input_shape=(5,), activation='relu'))\n",
    "    model.add(Dense(16, activation='relu'))\n",
    "    model.add(Dense(1, activation='sigmoid'))\n",
    "    # Compile model\n",
    "    model.compile(loss='binary_crossentropy', optimizer='adam', metrics=['accuracy'])\n",
    "    return model\n",
    "\n",
    "# fix random seed for reproducibility\n",
    "seed = 7\n",
    "tf.random.set_seed(seed)\n",
    "# load dataset\n",
    "dataset = pd.read_excel(\"default_cc_clients.xlsx\", header=1)\n",
    "# split into input (X) and output (Y) variables\n",
    "dataset.drop(['ID', 'PAY_0', 'PAY_2', 'PAY_3', 'PAY_4', 'PAY_5', 'PAY_6'], axis=1, inplace=True)\n",
    "dataset.drop(['BILL_AMT1', 'BILL_AMT2', 'BILL_AMT3', 'BILL_AMT4', 'BILL_AMT5', 'BILL_AMT6'], axis=1, inplace=True)\n",
    "dataset.drop(['PAY_AMT1', 'PAY_AMT2', 'PAY_AMT3', 'PAY_AMT4', 'PAY_AMT5', 'PAY_AMT6'], axis=1, inplace=True)"
   ]
  },
  {
   "cell_type": "code",
   "execution_count": 29,
   "metadata": {},
   "outputs": [],
   "source": [
    "dataset.head()\n",
    "X = dataset.iloc[:,0:5]\n",
    "Y = dataset.iloc[:,5]"
   ]
  },
  {
   "cell_type": "code",
   "execution_count": 30,
   "metadata": {},
   "outputs": [
    {
     "data": {
      "text/html": [
       "<div>\n",
       "<style scoped>\n",
       "    .dataframe tbody tr th:only-of-type {\n",
       "        vertical-align: middle;\n",
       "    }\n",
       "\n",
       "    .dataframe tbody tr th {\n",
       "        vertical-align: top;\n",
       "    }\n",
       "\n",
       "    .dataframe thead th {\n",
       "        text-align: right;\n",
       "    }\n",
       "</style>\n",
       "<table border=\"1\" class=\"dataframe\">\n",
       "  <thead>\n",
       "    <tr style=\"text-align: right;\">\n",
       "      <th></th>\n",
       "      <th>LIMIT_BAL</th>\n",
       "      <th>SEX</th>\n",
       "      <th>EDUCATION</th>\n",
       "      <th>MARRIAGE</th>\n",
       "      <th>AGE</th>\n",
       "    </tr>\n",
       "  </thead>\n",
       "  <tbody>\n",
       "    <tr>\n",
       "      <th>0</th>\n",
       "      <td>20000</td>\n",
       "      <td>2</td>\n",
       "      <td>2</td>\n",
       "      <td>1</td>\n",
       "      <td>24</td>\n",
       "    </tr>\n",
       "    <tr>\n",
       "      <th>1</th>\n",
       "      <td>120000</td>\n",
       "      <td>2</td>\n",
       "      <td>2</td>\n",
       "      <td>2</td>\n",
       "      <td>26</td>\n",
       "    </tr>\n",
       "    <tr>\n",
       "      <th>2</th>\n",
       "      <td>90000</td>\n",
       "      <td>2</td>\n",
       "      <td>2</td>\n",
       "      <td>2</td>\n",
       "      <td>34</td>\n",
       "    </tr>\n",
       "    <tr>\n",
       "      <th>3</th>\n",
       "      <td>50000</td>\n",
       "      <td>2</td>\n",
       "      <td>2</td>\n",
       "      <td>1</td>\n",
       "      <td>37</td>\n",
       "    </tr>\n",
       "    <tr>\n",
       "      <th>4</th>\n",
       "      <td>50000</td>\n",
       "      <td>1</td>\n",
       "      <td>2</td>\n",
       "      <td>1</td>\n",
       "      <td>57</td>\n",
       "    </tr>\n",
       "    <tr>\n",
       "      <th>...</th>\n",
       "      <td>...</td>\n",
       "      <td>...</td>\n",
       "      <td>...</td>\n",
       "      <td>...</td>\n",
       "      <td>...</td>\n",
       "    </tr>\n",
       "    <tr>\n",
       "      <th>29995</th>\n",
       "      <td>220000</td>\n",
       "      <td>1</td>\n",
       "      <td>3</td>\n",
       "      <td>1</td>\n",
       "      <td>39</td>\n",
       "    </tr>\n",
       "    <tr>\n",
       "      <th>29996</th>\n",
       "      <td>150000</td>\n",
       "      <td>1</td>\n",
       "      <td>3</td>\n",
       "      <td>2</td>\n",
       "      <td>43</td>\n",
       "    </tr>\n",
       "    <tr>\n",
       "      <th>29997</th>\n",
       "      <td>30000</td>\n",
       "      <td>1</td>\n",
       "      <td>2</td>\n",
       "      <td>2</td>\n",
       "      <td>37</td>\n",
       "    </tr>\n",
       "    <tr>\n",
       "      <th>29998</th>\n",
       "      <td>80000</td>\n",
       "      <td>1</td>\n",
       "      <td>3</td>\n",
       "      <td>1</td>\n",
       "      <td>41</td>\n",
       "    </tr>\n",
       "    <tr>\n",
       "      <th>29999</th>\n",
       "      <td>50000</td>\n",
       "      <td>1</td>\n",
       "      <td>2</td>\n",
       "      <td>1</td>\n",
       "      <td>46</td>\n",
       "    </tr>\n",
       "  </tbody>\n",
       "</table>\n",
       "<p>30000 rows Ã— 5 columns</p>\n",
       "</div>"
      ],
      "text/plain": [
       "       LIMIT_BAL  SEX  EDUCATION  MARRIAGE  AGE\n",
       "0          20000    2          2         1   24\n",
       "1         120000    2          2         2   26\n",
       "2          90000    2          2         2   34\n",
       "3          50000    2          2         1   37\n",
       "4          50000    1          2         1   57\n",
       "...          ...  ...        ...       ...  ...\n",
       "29995     220000    1          3         1   39\n",
       "29996     150000    1          3         2   43\n",
       "29997      30000    1          2         2   37\n",
       "29998      80000    1          3         1   41\n",
       "29999      50000    1          2         1   46\n",
       "\n",
       "[30000 rows x 5 columns]"
      ]
     },
     "execution_count": 30,
     "metadata": {},
     "output_type": "execute_result"
    }
   ],
   "source": [
    "X"
   ]
  },
  {
   "cell_type": "code",
   "execution_count": 31,
   "metadata": {},
   "outputs": [
    {
     "data": {
      "text/plain": [
       "0        1\n",
       "1        1\n",
       "2        0\n",
       "3        0\n",
       "4        0\n",
       "        ..\n",
       "29995    0\n",
       "29996    0\n",
       "29997    1\n",
       "29998    1\n",
       "29999    1\n",
       "Name: default payment next month, Length: 30000, dtype: int64"
      ]
     },
     "execution_count": 31,
     "metadata": {},
     "output_type": "execute_result"
    }
   ],
   "source": [
    "Y"
   ]
  },
  {
   "cell_type": "code",
   "execution_count": 32,
   "metadata": {},
   "outputs": [],
   "source": [
    "\n",
    "# create model\n",
    "model = KerasClassifier(model=create_model, verbose=0)\n",
    "\n",
    "# define the grid search parameters\n",
    "batch_size = [60, 80, 100]\n",
    "epochs = [10, 50, 100]\n",
    "param_grid = dict(batch_size=batch_size, epochs=epochs)"
   ]
  },
  {
   "cell_type": "code",
   "execution_count": 33,
   "metadata": {},
   "outputs": [
    {
     "name": "stdout",
     "output_type": "stream",
     "text": [
      "Best: 0.775000 using {'batch_size': 60, 'epochs': 100}\n",
      "0.592100 (0.262266) with: {'batch_size': 60, 'epochs': 10}\n",
      "0.592900 (0.262832) with: {'batch_size': 60, 'epochs': 50}\n",
      "0.775000 (0.005374) with: {'batch_size': 60, 'epochs': 100}\n",
      "0.407067 (0.262855) with: {'batch_size': 80, 'epochs': 10}\n",
      "0.592333 (0.262431) with: {'batch_size': 80, 'epochs': 50}\n",
      "0.589400 (0.260395) with: {'batch_size': 80, 'epochs': 100}\n",
      "0.592467 (0.262526) with: {'batch_size': 100, 'epochs': 10}\n",
      "0.592767 (0.262738) with: {'batch_size': 100, 'epochs': 50}\n",
      "0.769000 (0.012737) with: {'batch_size': 100, 'epochs': 100}\n"
     ]
    }
   ],
   "source": [
    "# Grid search\n",
    "grid = GridSearchCV(estimator=model, param_grid=param_grid, n_jobs=1, cv=3)\n",
    "grid_result = grid.fit(X, Y)\n",
    "\n",
    "# summarize results\n",
    "print(\"Best: %f using %s\" % (grid_result.best_score_, grid_result.best_params_))\n",
    "means = grid_result.cv_results_['mean_test_score']\n",
    "stds = grid_result.cv_results_['std_test_score']\n",
    "params = grid_result.cv_results_['params']\n",
    "for mean, stdev, param in zip(means, stds, params):\n",
    "    print(\"%f (%f) with: %r\" % (mean, stdev, param))"
   ]
  },
  {
   "cell_type": "code",
   "execution_count": 34,
   "metadata": {},
   "outputs": [
    {
     "name": "stdout",
     "output_type": "stream",
     "text": [
      "Best: 0.767700 using {'epochs': 100, 'batch_size': 80}\n",
      "0.592600 (0.262620) with: {'epochs': 10, 'batch_size': 60}\n",
      "0.577167 (0.252056) with: {'epochs': 50, 'batch_size': 60}\n",
      "0.693100 (0.063185) with: {'epochs': 100, 'batch_size': 60}\n",
      "0.593133 (0.262997) with: {'epochs': 10, 'batch_size': 80}\n",
      "0.725400 (0.039918) with: {'epochs': 50, 'batch_size': 80}\n",
      "0.767700 (0.014171) with: {'epochs': 100, 'batch_size': 80}\n",
      "0.591100 (0.261568) with: {'epochs': 10, 'batch_size': 100}\n",
      "0.568267 (0.245739) with: {'epochs': 50, 'batch_size': 100}\n",
      "0.565200 (0.245205) with: {'epochs': 100, 'batch_size': 100}\n"
     ]
    }
   ],
   "source": [
    "# Random search\n",
    "grid = RandomizedSearchCV(estimator=model, param_distributions=param_grid, n_jobs=1, cv=3)\n",
    "grid_result = grid.fit(X, Y)\n",
    "\n",
    "# summarize results\n",
    "print(\"Best: %f using %s\" % (grid_result.best_score_, grid_result.best_params_))\n",
    "means = grid_result.cv_results_['mean_test_score']\n",
    "stds = grid_result.cv_results_['std_test_score']\n",
    "params = grid_result.cv_results_['params']\n",
    "for mean, stdev, param in zip(means, stds, params):\n",
    "    print(\"%f (%f) with: %r\" % (mean, stdev, param))"
   ]
  },
  {
   "cell_type": "markdown",
   "metadata": {},
   "source": [
    "## OPtimization Alg. Tunning"
   ]
  },
  {
   "cell_type": "code",
   "execution_count": 35,
   "metadata": {},
   "outputs": [],
   "source": [
    "# Optimization Alg. Tunning\n",
    "def create_model():\n",
    " # create model\n",
    " model = Sequential()\n",
    " model.add(Dense(12, input_shape=(5,), activation='relu'))\n",
    " model.add(Dense(1, activation='sigmoid'))\n",
    " # return model without compile\n",
    " return model"
   ]
  },
  {
   "cell_type": "code",
   "execution_count": 37,
   "metadata": {},
   "outputs": [],
   "source": [
    "# fix random seed for reproducibility\n",
    "seed = 7\n",
    "tf.random.set_seed(seed)\n",
    "# create model\n",
    "model = KerasClassifier(model=create_model, loss=\"binary_crossentropy\", epochs=100, batch_size=10, verbose=0)\n",
    "# define the grid search parameters\n",
    "optimizer = ['SGD', 'RMSprop', 'Adagrad', 'Adadelta', 'Adam', 'Adamax', 'Nadam']\n",
    "param_grid = dict(optimizer=optimizer)"
   ]
  },
  {
   "cell_type": "code",
   "execution_count": 38,
   "metadata": {},
   "outputs": [
    {
     "ename": "ValueError",
     "evalue": "\nAll the 21 fits failed.\nIt is very likely that your model is misconfigured.\nYou can try to debug the error by setting error_score='raise'.\n\nBelow are more details about the failures:\n--------------------------------------------------------------------------------\n1 fits failed with the following error:\nTraceback (most recent call last):\n  File \"c:\\Users\\AndrÃ¨s DLR\\AppData\\Local\\Programs\\Python\\Python310\\lib\\site-packages\\sklearn\\model_selection\\_validation.py\", line 686, in _fit_and_score\n    estimator.fit(X_train, y_train, **fit_params)\n  File \"c:\\Users\\AndrÃ¨s DLR\\AppData\\Local\\Programs\\Python\\Python310\\lib\\site-packages\\scikeras\\wrappers.py\", line 1491, in fit\n    super().fit(X=X, y=y, sample_weight=sample_weight, **kwargs)\n  File \"c:\\Users\\AndrÃ¨s DLR\\AppData\\Local\\Programs\\Python\\Python310\\lib\\site-packages\\scikeras\\wrappers.py\", line 760, in fit\n    self._fit(\n  File \"c:\\Users\\AndrÃ¨s DLR\\AppData\\Local\\Programs\\Python\\Python310\\lib\\site-packages\\scikeras\\wrappers.py\", line 928, in _fit\n    self._fit_keras_model(\n  File \"c:\\Users\\AndrÃ¨s DLR\\AppData\\Local\\Programs\\Python\\Python310\\lib\\site-packages\\scikeras\\wrappers.py\", line 524, in _fit_keras_model\n    hist = self.model_.fit(x=X, y=y, **fit_args)\n  File \"c:\\Users\\AndrÃ¨s DLR\\AppData\\Local\\Programs\\Python\\Python310\\lib\\site-packages\\keras\\src\\utils\\traceback_utils.py\", line 70, in error_handler\n    raise e.with_traceback(filtered_tb) from None\n  File \"C:\\Users\\ANDRSD~1\\AppData\\Local\\Temp\\__autograph_generated_filethx4_r06.py\", line 15, in tf__train_function\n    retval_ = ag__.converted_call(ag__.ld(step_function), (ag__.ld(self), ag__.ld(iterator)), None, fscope)\nValueError: in user code:\n\n    File \"c:\\Users\\AndrÃ¨s DLR\\AppData\\Local\\Programs\\Python\\Python310\\lib\\site-packages\\keras\\src\\engine\\training.py\", line 1338, in train_function  *\n        return step_function(self, iterator)\n    File \"c:\\Users\\AndrÃ¨s DLR\\AppData\\Local\\Programs\\Python\\Python310\\lib\\site-packages\\keras\\src\\engine\\training.py\", line 1322, in step_function  **\n        outputs = model.distribute_strategy.run(run_step, args=(data,))\n    File \"c:\\Users\\AndrÃ¨s DLR\\AppData\\Local\\Programs\\Python\\Python310\\lib\\site-packages\\keras\\src\\engine\\training.py\", line 1303, in run_step  **\n        outputs = model.train_step(data)\n    File \"c:\\Users\\AndrÃ¨s DLR\\AppData\\Local\\Programs\\Python\\Python310\\lib\\site-packages\\keras\\src\\engine\\training.py\", line 1080, in train_step\n        y_pred = self(x, training=True)\n    File \"c:\\Users\\AndrÃ¨s DLR\\AppData\\Local\\Programs\\Python\\Python310\\lib\\site-packages\\keras\\src\\utils\\traceback_utils.py\", line 70, in error_handler\n        raise e.with_traceback(filtered_tb) from None\n    File \"c:\\Users\\AndrÃ¨s DLR\\AppData\\Local\\Programs\\Python\\Python310\\lib\\site-packages\\keras\\src\\engine\\input_spec.py\", line 298, in assert_input_compatibility\n        raise ValueError(\n\n    ValueError: Input 0 of layer \"sequential_83\" is incompatible with the layer: expected shape=(None, 8), found shape=(10, 5)\n\n\n--------------------------------------------------------------------------------\n1 fits failed with the following error:\nTraceback (most recent call last):\n  File \"c:\\Users\\AndrÃ¨s DLR\\AppData\\Local\\Programs\\Python\\Python310\\lib\\site-packages\\sklearn\\model_selection\\_validation.py\", line 686, in _fit_and_score\n    estimator.fit(X_train, y_train, **fit_params)\n  File \"c:\\Users\\AndrÃ¨s DLR\\AppData\\Local\\Programs\\Python\\Python310\\lib\\site-packages\\scikeras\\wrappers.py\", line 1491, in fit\n    super().fit(X=X, y=y, sample_weight=sample_weight, **kwargs)\n  File \"c:\\Users\\AndrÃ¨s DLR\\AppData\\Local\\Programs\\Python\\Python310\\lib\\site-packages\\scikeras\\wrappers.py\", line 760, in fit\n    self._fit(\n  File \"c:\\Users\\AndrÃ¨s DLR\\AppData\\Local\\Programs\\Python\\Python310\\lib\\site-packages\\scikeras\\wrappers.py\", line 928, in _fit\n    self._fit_keras_model(\n  File \"c:\\Users\\AndrÃ¨s DLR\\AppData\\Local\\Programs\\Python\\Python310\\lib\\site-packages\\scikeras\\wrappers.py\", line 524, in _fit_keras_model\n    hist = self.model_.fit(x=X, y=y, **fit_args)\n  File \"c:\\Users\\AndrÃ¨s DLR\\AppData\\Local\\Programs\\Python\\Python310\\lib\\site-packages\\keras\\src\\utils\\traceback_utils.py\", line 70, in error_handler\n    raise e.with_traceback(filtered_tb) from None\n  File \"C:\\Users\\ANDRSD~1\\AppData\\Local\\Temp\\__autograph_generated_filethx4_r06.py\", line 15, in tf__train_function\n    retval_ = ag__.converted_call(ag__.ld(step_function), (ag__.ld(self), ag__.ld(iterator)), None, fscope)\nValueError: in user code:\n\n    File \"c:\\Users\\AndrÃ¨s DLR\\AppData\\Local\\Programs\\Python\\Python310\\lib\\site-packages\\keras\\src\\engine\\training.py\", line 1338, in train_function  *\n        return step_function(self, iterator)\n    File \"c:\\Users\\AndrÃ¨s DLR\\AppData\\Local\\Programs\\Python\\Python310\\lib\\site-packages\\keras\\src\\engine\\training.py\", line 1322, in step_function  **\n        outputs = model.distribute_strategy.run(run_step, args=(data,))\n    File \"c:\\Users\\AndrÃ¨s DLR\\AppData\\Local\\Programs\\Python\\Python310\\lib\\site-packages\\keras\\src\\engine\\training.py\", line 1303, in run_step  **\n        outputs = model.train_step(data)\n    File \"c:\\Users\\AndrÃ¨s DLR\\AppData\\Local\\Programs\\Python\\Python310\\lib\\site-packages\\keras\\src\\engine\\training.py\", line 1080, in train_step\n        y_pred = self(x, training=True)\n    File \"c:\\Users\\AndrÃ¨s DLR\\AppData\\Local\\Programs\\Python\\Python310\\lib\\site-packages\\keras\\src\\utils\\traceback_utils.py\", line 70, in error_handler\n        raise e.with_traceback(filtered_tb) from None\n    File \"c:\\Users\\AndrÃ¨s DLR\\AppData\\Local\\Programs\\Python\\Python310\\lib\\site-packages\\keras\\src\\engine\\input_spec.py\", line 298, in assert_input_compatibility\n        raise ValueError(\n\n    ValueError: Input 0 of layer \"sequential_84\" is incompatible with the layer: expected shape=(None, 8), found shape=(10, 5)\n\n\n--------------------------------------------------------------------------------\n1 fits failed with the following error:\nTraceback (most recent call last):\n  File \"c:\\Users\\AndrÃ¨s DLR\\AppData\\Local\\Programs\\Python\\Python310\\lib\\site-packages\\sklearn\\model_selection\\_validation.py\", line 686, in _fit_and_score\n    estimator.fit(X_train, y_train, **fit_params)\n  File \"c:\\Users\\AndrÃ¨s DLR\\AppData\\Local\\Programs\\Python\\Python310\\lib\\site-packages\\scikeras\\wrappers.py\", line 1491, in fit\n    super().fit(X=X, y=y, sample_weight=sample_weight, **kwargs)\n  File \"c:\\Users\\AndrÃ¨s DLR\\AppData\\Local\\Programs\\Python\\Python310\\lib\\site-packages\\scikeras\\wrappers.py\", line 760, in fit\n    self._fit(\n  File \"c:\\Users\\AndrÃ¨s DLR\\AppData\\Local\\Programs\\Python\\Python310\\lib\\site-packages\\scikeras\\wrappers.py\", line 928, in _fit\n    self._fit_keras_model(\n  File \"c:\\Users\\AndrÃ¨s DLR\\AppData\\Local\\Programs\\Python\\Python310\\lib\\site-packages\\scikeras\\wrappers.py\", line 524, in _fit_keras_model\n    hist = self.model_.fit(x=X, y=y, **fit_args)\n  File \"c:\\Users\\AndrÃ¨s DLR\\AppData\\Local\\Programs\\Python\\Python310\\lib\\site-packages\\keras\\src\\utils\\traceback_utils.py\", line 70, in error_handler\n    raise e.with_traceback(filtered_tb) from None\n  File \"C:\\Users\\ANDRSD~1\\AppData\\Local\\Temp\\__autograph_generated_filethx4_r06.py\", line 15, in tf__train_function\n    retval_ = ag__.converted_call(ag__.ld(step_function), (ag__.ld(self), ag__.ld(iterator)), None, fscope)\nValueError: in user code:\n\n    File \"c:\\Users\\AndrÃ¨s DLR\\AppData\\Local\\Programs\\Python\\Python310\\lib\\site-packages\\keras\\src\\engine\\training.py\", line 1338, in train_function  *\n        return step_function(self, iterator)\n    File \"c:\\Users\\AndrÃ¨s DLR\\AppData\\Local\\Programs\\Python\\Python310\\lib\\site-packages\\keras\\src\\engine\\training.py\", line 1322, in step_function  **\n        outputs = model.distribute_strategy.run(run_step, args=(data,))\n    File \"c:\\Users\\AndrÃ¨s DLR\\AppData\\Local\\Programs\\Python\\Python310\\lib\\site-packages\\keras\\src\\engine\\training.py\", line 1303, in run_step  **\n        outputs = model.train_step(data)\n    File \"c:\\Users\\AndrÃ¨s DLR\\AppData\\Local\\Programs\\Python\\Python310\\lib\\site-packages\\keras\\src\\engine\\training.py\", line 1080, in train_step\n        y_pred = self(x, training=True)\n    File \"c:\\Users\\AndrÃ¨s DLR\\AppData\\Local\\Programs\\Python\\Python310\\lib\\site-packages\\keras\\src\\utils\\traceback_utils.py\", line 70, in error_handler\n        raise e.with_traceback(filtered_tb) from None\n    File \"c:\\Users\\AndrÃ¨s DLR\\AppData\\Local\\Programs\\Python\\Python310\\lib\\site-packages\\keras\\src\\engine\\input_spec.py\", line 298, in assert_input_compatibility\n        raise ValueError(\n\n    ValueError: Input 0 of layer \"sequential_85\" is incompatible with the layer: expected shape=(None, 8), found shape=(10, 5)\n\n\n--------------------------------------------------------------------------------\n1 fits failed with the following error:\nTraceback (most recent call last):\n  File \"c:\\Users\\AndrÃ¨s DLR\\AppData\\Local\\Programs\\Python\\Python310\\lib\\site-packages\\sklearn\\model_selection\\_validation.py\", line 686, in _fit_and_score\n    estimator.fit(X_train, y_train, **fit_params)\n  File \"c:\\Users\\AndrÃ¨s DLR\\AppData\\Local\\Programs\\Python\\Python310\\lib\\site-packages\\scikeras\\wrappers.py\", line 1491, in fit\n    super().fit(X=X, y=y, sample_weight=sample_weight, **kwargs)\n  File \"c:\\Users\\AndrÃ¨s DLR\\AppData\\Local\\Programs\\Python\\Python310\\lib\\site-packages\\scikeras\\wrappers.py\", line 760, in fit\n    self._fit(\n  File \"c:\\Users\\AndrÃ¨s DLR\\AppData\\Local\\Programs\\Python\\Python310\\lib\\site-packages\\scikeras\\wrappers.py\", line 928, in _fit\n    self._fit_keras_model(\n  File \"c:\\Users\\AndrÃ¨s DLR\\AppData\\Local\\Programs\\Python\\Python310\\lib\\site-packages\\scikeras\\wrappers.py\", line 524, in _fit_keras_model\n    hist = self.model_.fit(x=X, y=y, **fit_args)\n  File \"c:\\Users\\AndrÃ¨s DLR\\AppData\\Local\\Programs\\Python\\Python310\\lib\\site-packages\\keras\\src\\utils\\traceback_utils.py\", line 70, in error_handler\n    raise e.with_traceback(filtered_tb) from None\n  File \"C:\\Users\\ANDRSD~1\\AppData\\Local\\Temp\\__autograph_generated_filethx4_r06.py\", line 15, in tf__train_function\n    retval_ = ag__.converted_call(ag__.ld(step_function), (ag__.ld(self), ag__.ld(iterator)), None, fscope)\nValueError: in user code:\n\n    File \"c:\\Users\\AndrÃ¨s DLR\\AppData\\Local\\Programs\\Python\\Python310\\lib\\site-packages\\keras\\src\\engine\\training.py\", line 1338, in train_function  *\n        return step_function(self, iterator)\n    File \"c:\\Users\\AndrÃ¨s DLR\\AppData\\Local\\Programs\\Python\\Python310\\lib\\site-packages\\keras\\src\\engine\\training.py\", line 1322, in step_function  **\n        outputs = model.distribute_strategy.run(run_step, args=(data,))\n    File \"c:\\Users\\AndrÃ¨s DLR\\AppData\\Local\\Programs\\Python\\Python310\\lib\\site-packages\\keras\\src\\engine\\training.py\", line 1303, in run_step  **\n        outputs = model.train_step(data)\n    File \"c:\\Users\\AndrÃ¨s DLR\\AppData\\Local\\Programs\\Python\\Python310\\lib\\site-packages\\keras\\src\\engine\\training.py\", line 1080, in train_step\n        y_pred = self(x, training=True)\n    File \"c:\\Users\\AndrÃ¨s DLR\\AppData\\Local\\Programs\\Python\\Python310\\lib\\site-packages\\keras\\src\\utils\\traceback_utils.py\", line 70, in error_handler\n        raise e.with_traceback(filtered_tb) from None\n    File \"c:\\Users\\AndrÃ¨s DLR\\AppData\\Local\\Programs\\Python\\Python310\\lib\\site-packages\\keras\\src\\engine\\input_spec.py\", line 298, in assert_input_compatibility\n        raise ValueError(\n\n    ValueError: Input 0 of layer \"sequential_86\" is incompatible with the layer: expected shape=(None, 8), found shape=(10, 5)\n\n\n--------------------------------------------------------------------------------\n1 fits failed with the following error:\nTraceback (most recent call last):\n  File \"c:\\Users\\AndrÃ¨s DLR\\AppData\\Local\\Programs\\Python\\Python310\\lib\\site-packages\\sklearn\\model_selection\\_validation.py\", line 686, in _fit_and_score\n    estimator.fit(X_train, y_train, **fit_params)\n  File \"c:\\Users\\AndrÃ¨s DLR\\AppData\\Local\\Programs\\Python\\Python310\\lib\\site-packages\\scikeras\\wrappers.py\", line 1491, in fit\n    super().fit(X=X, y=y, sample_weight=sample_weight, **kwargs)\n  File \"c:\\Users\\AndrÃ¨s DLR\\AppData\\Local\\Programs\\Python\\Python310\\lib\\site-packages\\scikeras\\wrappers.py\", line 760, in fit\n    self._fit(\n  File \"c:\\Users\\AndrÃ¨s DLR\\AppData\\Local\\Programs\\Python\\Python310\\lib\\site-packages\\scikeras\\wrappers.py\", line 928, in _fit\n    self._fit_keras_model(\n  File \"c:\\Users\\AndrÃ¨s DLR\\AppData\\Local\\Programs\\Python\\Python310\\lib\\site-packages\\scikeras\\wrappers.py\", line 524, in _fit_keras_model\n    hist = self.model_.fit(x=X, y=y, **fit_args)\n  File \"c:\\Users\\AndrÃ¨s DLR\\AppData\\Local\\Programs\\Python\\Python310\\lib\\site-packages\\keras\\src\\utils\\traceback_utils.py\", line 70, in error_handler\n    raise e.with_traceback(filtered_tb) from None\n  File \"C:\\Users\\ANDRSD~1\\AppData\\Local\\Temp\\__autograph_generated_filethx4_r06.py\", line 15, in tf__train_function\n    retval_ = ag__.converted_call(ag__.ld(step_function), (ag__.ld(self), ag__.ld(iterator)), None, fscope)\nValueError: in user code:\n\n    File \"c:\\Users\\AndrÃ¨s DLR\\AppData\\Local\\Programs\\Python\\Python310\\lib\\site-packages\\keras\\src\\engine\\training.py\", line 1338, in train_function  *\n        return step_function(self, iterator)\n    File \"c:\\Users\\AndrÃ¨s DLR\\AppData\\Local\\Programs\\Python\\Python310\\lib\\site-packages\\keras\\src\\engine\\training.py\", line 1322, in step_function  **\n        outputs = model.distribute_strategy.run(run_step, args=(data,))\n    File \"c:\\Users\\AndrÃ¨s DLR\\AppData\\Local\\Programs\\Python\\Python310\\lib\\site-packages\\keras\\src\\engine\\training.py\", line 1303, in run_step  **\n        outputs = model.train_step(data)\n    File \"c:\\Users\\AndrÃ¨s DLR\\AppData\\Local\\Programs\\Python\\Python310\\lib\\site-packages\\keras\\src\\engine\\training.py\", line 1080, in train_step\n        y_pred = self(x, training=True)\n    File \"c:\\Users\\AndrÃ¨s DLR\\AppData\\Local\\Programs\\Python\\Python310\\lib\\site-packages\\keras\\src\\utils\\traceback_utils.py\", line 70, in error_handler\n        raise e.with_traceback(filtered_tb) from None\n    File \"c:\\Users\\AndrÃ¨s DLR\\AppData\\Local\\Programs\\Python\\Python310\\lib\\site-packages\\keras\\src\\engine\\input_spec.py\", line 298, in assert_input_compatibility\n        raise ValueError(\n\n    ValueError: Input 0 of layer \"sequential_87\" is incompatible with the layer: expected shape=(None, 8), found shape=(10, 5)\n\n\n--------------------------------------------------------------------------------\n1 fits failed with the following error:\nTraceback (most recent call last):\n  File \"c:\\Users\\AndrÃ¨s DLR\\AppData\\Local\\Programs\\Python\\Python310\\lib\\site-packages\\sklearn\\model_selection\\_validation.py\", line 686, in _fit_and_score\n    estimator.fit(X_train, y_train, **fit_params)\n  File \"c:\\Users\\AndrÃ¨s DLR\\AppData\\Local\\Programs\\Python\\Python310\\lib\\site-packages\\scikeras\\wrappers.py\", line 1491, in fit\n    super().fit(X=X, y=y, sample_weight=sample_weight, **kwargs)\n  File \"c:\\Users\\AndrÃ¨s DLR\\AppData\\Local\\Programs\\Python\\Python310\\lib\\site-packages\\scikeras\\wrappers.py\", line 760, in fit\n    self._fit(\n  File \"c:\\Users\\AndrÃ¨s DLR\\AppData\\Local\\Programs\\Python\\Python310\\lib\\site-packages\\scikeras\\wrappers.py\", line 928, in _fit\n    self._fit_keras_model(\n  File \"c:\\Users\\AndrÃ¨s DLR\\AppData\\Local\\Programs\\Python\\Python310\\lib\\site-packages\\scikeras\\wrappers.py\", line 524, in _fit_keras_model\n    hist = self.model_.fit(x=X, y=y, **fit_args)\n  File \"c:\\Users\\AndrÃ¨s DLR\\AppData\\Local\\Programs\\Python\\Python310\\lib\\site-packages\\keras\\src\\utils\\traceback_utils.py\", line 70, in error_handler\n    raise e.with_traceback(filtered_tb) from None\n  File \"C:\\Users\\ANDRSD~1\\AppData\\Local\\Temp\\__autograph_generated_filethx4_r06.py\", line 15, in tf__train_function\n    retval_ = ag__.converted_call(ag__.ld(step_function), (ag__.ld(self), ag__.ld(iterator)), None, fscope)\nValueError: in user code:\n\n    File \"c:\\Users\\AndrÃ¨s DLR\\AppData\\Local\\Programs\\Python\\Python310\\lib\\site-packages\\keras\\src\\engine\\training.py\", line 1338, in train_function  *\n        return step_function(self, iterator)\n    File \"c:\\Users\\AndrÃ¨s DLR\\AppData\\Local\\Programs\\Python\\Python310\\lib\\site-packages\\keras\\src\\engine\\training.py\", line 1322, in step_function  **\n        outputs = model.distribute_strategy.run(run_step, args=(data,))\n    File \"c:\\Users\\AndrÃ¨s DLR\\AppData\\Local\\Programs\\Python\\Python310\\lib\\site-packages\\keras\\src\\engine\\training.py\", line 1303, in run_step  **\n        outputs = model.train_step(data)\n    File \"c:\\Users\\AndrÃ¨s DLR\\AppData\\Local\\Programs\\Python\\Python310\\lib\\site-packages\\keras\\src\\engine\\training.py\", line 1080, in train_step\n        y_pred = self(x, training=True)\n    File \"c:\\Users\\AndrÃ¨s DLR\\AppData\\Local\\Programs\\Python\\Python310\\lib\\site-packages\\keras\\src\\utils\\traceback_utils.py\", line 70, in error_handler\n        raise e.with_traceback(filtered_tb) from None\n    File \"c:\\Users\\AndrÃ¨s DLR\\AppData\\Local\\Programs\\Python\\Python310\\lib\\site-packages\\keras\\src\\engine\\input_spec.py\", line 298, in assert_input_compatibility\n        raise ValueError(\n\n    ValueError: Input 0 of layer \"sequential_88\" is incompatible with the layer: expected shape=(None, 8), found shape=(10, 5)\n\n\n--------------------------------------------------------------------------------\n1 fits failed with the following error:\nTraceback (most recent call last):\n  File \"c:\\Users\\AndrÃ¨s DLR\\AppData\\Local\\Programs\\Python\\Python310\\lib\\site-packages\\sklearn\\model_selection\\_validation.py\", line 686, in _fit_and_score\n    estimator.fit(X_train, y_train, **fit_params)\n  File \"c:\\Users\\AndrÃ¨s DLR\\AppData\\Local\\Programs\\Python\\Python310\\lib\\site-packages\\scikeras\\wrappers.py\", line 1491, in fit\n    super().fit(X=X, y=y, sample_weight=sample_weight, **kwargs)\n  File \"c:\\Users\\AndrÃ¨s DLR\\AppData\\Local\\Programs\\Python\\Python310\\lib\\site-packages\\scikeras\\wrappers.py\", line 760, in fit\n    self._fit(\n  File \"c:\\Users\\AndrÃ¨s DLR\\AppData\\Local\\Programs\\Python\\Python310\\lib\\site-packages\\scikeras\\wrappers.py\", line 928, in _fit\n    self._fit_keras_model(\n  File \"c:\\Users\\AndrÃ¨s DLR\\AppData\\Local\\Programs\\Python\\Python310\\lib\\site-packages\\scikeras\\wrappers.py\", line 524, in _fit_keras_model\n    hist = self.model_.fit(x=X, y=y, **fit_args)\n  File \"c:\\Users\\AndrÃ¨s DLR\\AppData\\Local\\Programs\\Python\\Python310\\lib\\site-packages\\keras\\src\\utils\\traceback_utils.py\", line 70, in error_handler\n    raise e.with_traceback(filtered_tb) from None\n  File \"C:\\Users\\ANDRSD~1\\AppData\\Local\\Temp\\__autograph_generated_filethx4_r06.py\", line 15, in tf__train_function\n    retval_ = ag__.converted_call(ag__.ld(step_function), (ag__.ld(self), ag__.ld(iterator)), None, fscope)\nValueError: in user code:\n\n    File \"c:\\Users\\AndrÃ¨s DLR\\AppData\\Local\\Programs\\Python\\Python310\\lib\\site-packages\\keras\\src\\engine\\training.py\", line 1338, in train_function  *\n        return step_function(self, iterator)\n    File \"c:\\Users\\AndrÃ¨s DLR\\AppData\\Local\\Programs\\Python\\Python310\\lib\\site-packages\\keras\\src\\engine\\training.py\", line 1322, in step_function  **\n        outputs = model.distribute_strategy.run(run_step, args=(data,))\n    File \"c:\\Users\\AndrÃ¨s DLR\\AppData\\Local\\Programs\\Python\\Python310\\lib\\site-packages\\keras\\src\\engine\\training.py\", line 1303, in run_step  **\n        outputs = model.train_step(data)\n    File \"c:\\Users\\AndrÃ¨s DLR\\AppData\\Local\\Programs\\Python\\Python310\\lib\\site-packages\\keras\\src\\engine\\training.py\", line 1080, in train_step\n        y_pred = self(x, training=True)\n    File \"c:\\Users\\AndrÃ¨s DLR\\AppData\\Local\\Programs\\Python\\Python310\\lib\\site-packages\\keras\\src\\utils\\traceback_utils.py\", line 70, in error_handler\n        raise e.with_traceback(filtered_tb) from None\n    File \"c:\\Users\\AndrÃ¨s DLR\\AppData\\Local\\Programs\\Python\\Python310\\lib\\site-packages\\keras\\src\\engine\\input_spec.py\", line 298, in assert_input_compatibility\n        raise ValueError(\n\n    ValueError: Input 0 of layer \"sequential_89\" is incompatible with the layer: expected shape=(None, 8), found shape=(10, 5)\n\n\n--------------------------------------------------------------------------------\n1 fits failed with the following error:\nTraceback (most recent call last):\n  File \"c:\\Users\\AndrÃ¨s DLR\\AppData\\Local\\Programs\\Python\\Python310\\lib\\site-packages\\sklearn\\model_selection\\_validation.py\", line 686, in _fit_and_score\n    estimator.fit(X_train, y_train, **fit_params)\n  File \"c:\\Users\\AndrÃ¨s DLR\\AppData\\Local\\Programs\\Python\\Python310\\lib\\site-packages\\scikeras\\wrappers.py\", line 1491, in fit\n    super().fit(X=X, y=y, sample_weight=sample_weight, **kwargs)\n  File \"c:\\Users\\AndrÃ¨s DLR\\AppData\\Local\\Programs\\Python\\Python310\\lib\\site-packages\\scikeras\\wrappers.py\", line 760, in fit\n    self._fit(\n  File \"c:\\Users\\AndrÃ¨s DLR\\AppData\\Local\\Programs\\Python\\Python310\\lib\\site-packages\\scikeras\\wrappers.py\", line 928, in _fit\n    self._fit_keras_model(\n  File \"c:\\Users\\AndrÃ¨s DLR\\AppData\\Local\\Programs\\Python\\Python310\\lib\\site-packages\\scikeras\\wrappers.py\", line 524, in _fit_keras_model\n    hist = self.model_.fit(x=X, y=y, **fit_args)\n  File \"c:\\Users\\AndrÃ¨s DLR\\AppData\\Local\\Programs\\Python\\Python310\\lib\\site-packages\\keras\\src\\utils\\traceback_utils.py\", line 70, in error_handler\n    raise e.with_traceback(filtered_tb) from None\n  File \"C:\\Users\\ANDRSD~1\\AppData\\Local\\Temp\\__autograph_generated_filethx4_r06.py\", line 15, in tf__train_function\n    retval_ = ag__.converted_call(ag__.ld(step_function), (ag__.ld(self), ag__.ld(iterator)), None, fscope)\nValueError: in user code:\n\n    File \"c:\\Users\\AndrÃ¨s DLR\\AppData\\Local\\Programs\\Python\\Python310\\lib\\site-packages\\keras\\src\\engine\\training.py\", line 1338, in train_function  *\n        return step_function(self, iterator)\n    File \"c:\\Users\\AndrÃ¨s DLR\\AppData\\Local\\Programs\\Python\\Python310\\lib\\site-packages\\keras\\src\\engine\\training.py\", line 1322, in step_function  **\n        outputs = model.distribute_strategy.run(run_step, args=(data,))\n    File \"c:\\Users\\AndrÃ¨s DLR\\AppData\\Local\\Programs\\Python\\Python310\\lib\\site-packages\\keras\\src\\engine\\training.py\", line 1303, in run_step  **\n        outputs = model.train_step(data)\n    File \"c:\\Users\\AndrÃ¨s DLR\\AppData\\Local\\Programs\\Python\\Python310\\lib\\site-packages\\keras\\src\\engine\\training.py\", line 1080, in train_step\n        y_pred = self(x, training=True)\n    File \"c:\\Users\\AndrÃ¨s DLR\\AppData\\Local\\Programs\\Python\\Python310\\lib\\site-packages\\keras\\src\\utils\\traceback_utils.py\", line 70, in error_handler\n        raise e.with_traceback(filtered_tb) from None\n    File \"c:\\Users\\AndrÃ¨s DLR\\AppData\\Local\\Programs\\Python\\Python310\\lib\\site-packages\\keras\\src\\engine\\input_spec.py\", line 298, in assert_input_compatibility\n        raise ValueError(\n\n    ValueError: Input 0 of layer \"sequential_90\" is incompatible with the layer: expected shape=(None, 8), found shape=(10, 5)\n\n\n--------------------------------------------------------------------------------\n1 fits failed with the following error:\nTraceback (most recent call last):\n  File \"c:\\Users\\AndrÃ¨s DLR\\AppData\\Local\\Programs\\Python\\Python310\\lib\\site-packages\\sklearn\\model_selection\\_validation.py\", line 686, in _fit_and_score\n    estimator.fit(X_train, y_train, **fit_params)\n  File \"c:\\Users\\AndrÃ¨s DLR\\AppData\\Local\\Programs\\Python\\Python310\\lib\\site-packages\\scikeras\\wrappers.py\", line 1491, in fit\n    super().fit(X=X, y=y, sample_weight=sample_weight, **kwargs)\n  File \"c:\\Users\\AndrÃ¨s DLR\\AppData\\Local\\Programs\\Python\\Python310\\lib\\site-packages\\scikeras\\wrappers.py\", line 760, in fit\n    self._fit(\n  File \"c:\\Users\\AndrÃ¨s DLR\\AppData\\Local\\Programs\\Python\\Python310\\lib\\site-packages\\scikeras\\wrappers.py\", line 928, in _fit\n    self._fit_keras_model(\n  File \"c:\\Users\\AndrÃ¨s DLR\\AppData\\Local\\Programs\\Python\\Python310\\lib\\site-packages\\scikeras\\wrappers.py\", line 524, in _fit_keras_model\n    hist = self.model_.fit(x=X, y=y, **fit_args)\n  File \"c:\\Users\\AndrÃ¨s DLR\\AppData\\Local\\Programs\\Python\\Python310\\lib\\site-packages\\keras\\src\\utils\\traceback_utils.py\", line 70, in error_handler\n    raise e.with_traceback(filtered_tb) from None\n  File \"C:\\Users\\ANDRSD~1\\AppData\\Local\\Temp\\__autograph_generated_filethx4_r06.py\", line 15, in tf__train_function\n    retval_ = ag__.converted_call(ag__.ld(step_function), (ag__.ld(self), ag__.ld(iterator)), None, fscope)\nValueError: in user code:\n\n    File \"c:\\Users\\AndrÃ¨s DLR\\AppData\\Local\\Programs\\Python\\Python310\\lib\\site-packages\\keras\\src\\engine\\training.py\", line 1338, in train_function  *\n        return step_function(self, iterator)\n    File \"c:\\Users\\AndrÃ¨s DLR\\AppData\\Local\\Programs\\Python\\Python310\\lib\\site-packages\\keras\\src\\engine\\training.py\", line 1322, in step_function  **\n        outputs = model.distribute_strategy.run(run_step, args=(data,))\n    File \"c:\\Users\\AndrÃ¨s DLR\\AppData\\Local\\Programs\\Python\\Python310\\lib\\site-packages\\keras\\src\\engine\\training.py\", line 1303, in run_step  **\n        outputs = model.train_step(data)\n    File \"c:\\Users\\AndrÃ¨s DLR\\AppData\\Local\\Programs\\Python\\Python310\\lib\\site-packages\\keras\\src\\engine\\training.py\", line 1080, in train_step\n        y_pred = self(x, training=True)\n    File \"c:\\Users\\AndrÃ¨s DLR\\AppData\\Local\\Programs\\Python\\Python310\\lib\\site-packages\\keras\\src\\utils\\traceback_utils.py\", line 70, in error_handler\n        raise e.with_traceback(filtered_tb) from None\n    File \"c:\\Users\\AndrÃ¨s DLR\\AppData\\Local\\Programs\\Python\\Python310\\lib\\site-packages\\keras\\src\\engine\\input_spec.py\", line 298, in assert_input_compatibility\n        raise ValueError(\n\n    ValueError: Input 0 of layer \"sequential_91\" is incompatible with the layer: expected shape=(None, 8), found shape=(10, 5)\n\n\n--------------------------------------------------------------------------------\n1 fits failed with the following error:\nTraceback (most recent call last):\n  File \"c:\\Users\\AndrÃ¨s DLR\\AppData\\Local\\Programs\\Python\\Python310\\lib\\site-packages\\sklearn\\model_selection\\_validation.py\", line 686, in _fit_and_score\n    estimator.fit(X_train, y_train, **fit_params)\n  File \"c:\\Users\\AndrÃ¨s DLR\\AppData\\Local\\Programs\\Python\\Python310\\lib\\site-packages\\scikeras\\wrappers.py\", line 1491, in fit\n    super().fit(X=X, y=y, sample_weight=sample_weight, **kwargs)\n  File \"c:\\Users\\AndrÃ¨s DLR\\AppData\\Local\\Programs\\Python\\Python310\\lib\\site-packages\\scikeras\\wrappers.py\", line 760, in fit\n    self._fit(\n  File \"c:\\Users\\AndrÃ¨s DLR\\AppData\\Local\\Programs\\Python\\Python310\\lib\\site-packages\\scikeras\\wrappers.py\", line 928, in _fit\n    self._fit_keras_model(\n  File \"c:\\Users\\AndrÃ¨s DLR\\AppData\\Local\\Programs\\Python\\Python310\\lib\\site-packages\\scikeras\\wrappers.py\", line 524, in _fit_keras_model\n    hist = self.model_.fit(x=X, y=y, **fit_args)\n  File \"c:\\Users\\AndrÃ¨s DLR\\AppData\\Local\\Programs\\Python\\Python310\\lib\\site-packages\\keras\\src\\utils\\traceback_utils.py\", line 70, in error_handler\n    raise e.with_traceback(filtered_tb) from None\n  File \"C:\\Users\\ANDRSD~1\\AppData\\Local\\Temp\\__autograph_generated_filethx4_r06.py\", line 15, in tf__train_function\n    retval_ = ag__.converted_call(ag__.ld(step_function), (ag__.ld(self), ag__.ld(iterator)), None, fscope)\nValueError: in user code:\n\n    File \"c:\\Users\\AndrÃ¨s DLR\\AppData\\Local\\Programs\\Python\\Python310\\lib\\site-packages\\keras\\src\\engine\\training.py\", line 1338, in train_function  *\n        return step_function(self, iterator)\n    File \"c:\\Users\\AndrÃ¨s DLR\\AppData\\Local\\Programs\\Python\\Python310\\lib\\site-packages\\keras\\src\\engine\\training.py\", line 1322, in step_function  **\n        outputs = model.distribute_strategy.run(run_step, args=(data,))\n    File \"c:\\Users\\AndrÃ¨s DLR\\AppData\\Local\\Programs\\Python\\Python310\\lib\\site-packages\\keras\\src\\engine\\training.py\", line 1303, in run_step  **\n        outputs = model.train_step(data)\n    File \"c:\\Users\\AndrÃ¨s DLR\\AppData\\Local\\Programs\\Python\\Python310\\lib\\site-packages\\keras\\src\\engine\\training.py\", line 1080, in train_step\n        y_pred = self(x, training=True)\n    File \"c:\\Users\\AndrÃ¨s DLR\\AppData\\Local\\Programs\\Python\\Python310\\lib\\site-packages\\keras\\src\\utils\\traceback_utils.py\", line 70, in error_handler\n        raise e.with_traceback(filtered_tb) from None\n    File \"c:\\Users\\AndrÃ¨s DLR\\AppData\\Local\\Programs\\Python\\Python310\\lib\\site-packages\\keras\\src\\engine\\input_spec.py\", line 298, in assert_input_compatibility\n        raise ValueError(\n\n    ValueError: Input 0 of layer \"sequential_92\" is incompatible with the layer: expected shape=(None, 8), found shape=(10, 5)\n\n\n--------------------------------------------------------------------------------\n1 fits failed with the following error:\nTraceback (most recent call last):\n  File \"c:\\Users\\AndrÃ¨s DLR\\AppData\\Local\\Programs\\Python\\Python310\\lib\\site-packages\\sklearn\\model_selection\\_validation.py\", line 686, in _fit_and_score\n    estimator.fit(X_train, y_train, **fit_params)\n  File \"c:\\Users\\AndrÃ¨s DLR\\AppData\\Local\\Programs\\Python\\Python310\\lib\\site-packages\\scikeras\\wrappers.py\", line 1491, in fit\n    super().fit(X=X, y=y, sample_weight=sample_weight, **kwargs)\n  File \"c:\\Users\\AndrÃ¨s DLR\\AppData\\Local\\Programs\\Python\\Python310\\lib\\site-packages\\scikeras\\wrappers.py\", line 760, in fit\n    self._fit(\n  File \"c:\\Users\\AndrÃ¨s DLR\\AppData\\Local\\Programs\\Python\\Python310\\lib\\site-packages\\scikeras\\wrappers.py\", line 928, in _fit\n    self._fit_keras_model(\n  File \"c:\\Users\\AndrÃ¨s DLR\\AppData\\Local\\Programs\\Python\\Python310\\lib\\site-packages\\scikeras\\wrappers.py\", line 524, in _fit_keras_model\n    hist = self.model_.fit(x=X, y=y, **fit_args)\n  File \"c:\\Users\\AndrÃ¨s DLR\\AppData\\Local\\Programs\\Python\\Python310\\lib\\site-packages\\keras\\src\\utils\\traceback_utils.py\", line 70, in error_handler\n    raise e.with_traceback(filtered_tb) from None\n  File \"C:\\Users\\ANDRSD~1\\AppData\\Local\\Temp\\__autograph_generated_filethx4_r06.py\", line 15, in tf__train_function\n    retval_ = ag__.converted_call(ag__.ld(step_function), (ag__.ld(self), ag__.ld(iterator)), None, fscope)\nValueError: in user code:\n\n    File \"c:\\Users\\AndrÃ¨s DLR\\AppData\\Local\\Programs\\Python\\Python310\\lib\\site-packages\\keras\\src\\engine\\training.py\", line 1338, in train_function  *\n        return step_function(self, iterator)\n    File \"c:\\Users\\AndrÃ¨s DLR\\AppData\\Local\\Programs\\Python\\Python310\\lib\\site-packages\\keras\\src\\engine\\training.py\", line 1322, in step_function  **\n        outputs = model.distribute_strategy.run(run_step, args=(data,))\n    File \"c:\\Users\\AndrÃ¨s DLR\\AppData\\Local\\Programs\\Python\\Python310\\lib\\site-packages\\keras\\src\\engine\\training.py\", line 1303, in run_step  **\n        outputs = model.train_step(data)\n    File \"c:\\Users\\AndrÃ¨s DLR\\AppData\\Local\\Programs\\Python\\Python310\\lib\\site-packages\\keras\\src\\engine\\training.py\", line 1080, in train_step\n        y_pred = self(x, training=True)\n    File \"c:\\Users\\AndrÃ¨s DLR\\AppData\\Local\\Programs\\Python\\Python310\\lib\\site-packages\\keras\\src\\utils\\traceback_utils.py\", line 70, in error_handler\n        raise e.with_traceback(filtered_tb) from None\n    File \"c:\\Users\\AndrÃ¨s DLR\\AppData\\Local\\Programs\\Python\\Python310\\lib\\site-packages\\keras\\src\\engine\\input_spec.py\", line 298, in assert_input_compatibility\n        raise ValueError(\n\n    ValueError: Input 0 of layer \"sequential_93\" is incompatible with the layer: expected shape=(None, 8), found shape=(10, 5)\n\n\n--------------------------------------------------------------------------------\n1 fits failed with the following error:\nTraceback (most recent call last):\n  File \"c:\\Users\\AndrÃ¨s DLR\\AppData\\Local\\Programs\\Python\\Python310\\lib\\site-packages\\sklearn\\model_selection\\_validation.py\", line 686, in _fit_and_score\n    estimator.fit(X_train, y_train, **fit_params)\n  File \"c:\\Users\\AndrÃ¨s DLR\\AppData\\Local\\Programs\\Python\\Python310\\lib\\site-packages\\scikeras\\wrappers.py\", line 1491, in fit\n    super().fit(X=X, y=y, sample_weight=sample_weight, **kwargs)\n  File \"c:\\Users\\AndrÃ¨s DLR\\AppData\\Local\\Programs\\Python\\Python310\\lib\\site-packages\\scikeras\\wrappers.py\", line 760, in fit\n    self._fit(\n  File \"c:\\Users\\AndrÃ¨s DLR\\AppData\\Local\\Programs\\Python\\Python310\\lib\\site-packages\\scikeras\\wrappers.py\", line 928, in _fit\n    self._fit_keras_model(\n  File \"c:\\Users\\AndrÃ¨s DLR\\AppData\\Local\\Programs\\Python\\Python310\\lib\\site-packages\\scikeras\\wrappers.py\", line 524, in _fit_keras_model\n    hist = self.model_.fit(x=X, y=y, **fit_args)\n  File \"c:\\Users\\AndrÃ¨s DLR\\AppData\\Local\\Programs\\Python\\Python310\\lib\\site-packages\\keras\\src\\utils\\traceback_utils.py\", line 70, in error_handler\n    raise e.with_traceback(filtered_tb) from None\n  File \"C:\\Users\\ANDRSD~1\\AppData\\Local\\Temp\\__autograph_generated_filethx4_r06.py\", line 15, in tf__train_function\n    retval_ = ag__.converted_call(ag__.ld(step_function), (ag__.ld(self), ag__.ld(iterator)), None, fscope)\nValueError: in user code:\n\n    File \"c:\\Users\\AndrÃ¨s DLR\\AppData\\Local\\Programs\\Python\\Python310\\lib\\site-packages\\keras\\src\\engine\\training.py\", line 1338, in train_function  *\n        return step_function(self, iterator)\n    File \"c:\\Users\\AndrÃ¨s DLR\\AppData\\Local\\Programs\\Python\\Python310\\lib\\site-packages\\keras\\src\\engine\\training.py\", line 1322, in step_function  **\n        outputs = model.distribute_strategy.run(run_step, args=(data,))\n    File \"c:\\Users\\AndrÃ¨s DLR\\AppData\\Local\\Programs\\Python\\Python310\\lib\\site-packages\\keras\\src\\engine\\training.py\", line 1303, in run_step  **\n        outputs = model.train_step(data)\n    File \"c:\\Users\\AndrÃ¨s DLR\\AppData\\Local\\Programs\\Python\\Python310\\lib\\site-packages\\keras\\src\\engine\\training.py\", line 1080, in train_step\n        y_pred = self(x, training=True)\n    File \"c:\\Users\\AndrÃ¨s DLR\\AppData\\Local\\Programs\\Python\\Python310\\lib\\site-packages\\keras\\src\\utils\\traceback_utils.py\", line 70, in error_handler\n        raise e.with_traceback(filtered_tb) from None\n    File \"c:\\Users\\AndrÃ¨s DLR\\AppData\\Local\\Programs\\Python\\Python310\\lib\\site-packages\\keras\\src\\engine\\input_spec.py\", line 298, in assert_input_compatibility\n        raise ValueError(\n\n    ValueError: Input 0 of layer \"sequential_94\" is incompatible with the layer: expected shape=(None, 8), found shape=(10, 5)\n\n\n--------------------------------------------------------------------------------\n1 fits failed with the following error:\nTraceback (most recent call last):\n  File \"c:\\Users\\AndrÃ¨s DLR\\AppData\\Local\\Programs\\Python\\Python310\\lib\\site-packages\\sklearn\\model_selection\\_validation.py\", line 686, in _fit_and_score\n    estimator.fit(X_train, y_train, **fit_params)\n  File \"c:\\Users\\AndrÃ¨s DLR\\AppData\\Local\\Programs\\Python\\Python310\\lib\\site-packages\\scikeras\\wrappers.py\", line 1491, in fit\n    super().fit(X=X, y=y, sample_weight=sample_weight, **kwargs)\n  File \"c:\\Users\\AndrÃ¨s DLR\\AppData\\Local\\Programs\\Python\\Python310\\lib\\site-packages\\scikeras\\wrappers.py\", line 760, in fit\n    self._fit(\n  File \"c:\\Users\\AndrÃ¨s DLR\\AppData\\Local\\Programs\\Python\\Python310\\lib\\site-packages\\scikeras\\wrappers.py\", line 928, in _fit\n    self._fit_keras_model(\n  File \"c:\\Users\\AndrÃ¨s DLR\\AppData\\Local\\Programs\\Python\\Python310\\lib\\site-packages\\scikeras\\wrappers.py\", line 524, in _fit_keras_model\n    hist = self.model_.fit(x=X, y=y, **fit_args)\n  File \"c:\\Users\\AndrÃ¨s DLR\\AppData\\Local\\Programs\\Python\\Python310\\lib\\site-packages\\keras\\src\\utils\\traceback_utils.py\", line 70, in error_handler\n    raise e.with_traceback(filtered_tb) from None\n  File \"C:\\Users\\ANDRSD~1\\AppData\\Local\\Temp\\__autograph_generated_filethx4_r06.py\", line 15, in tf__train_function\n    retval_ = ag__.converted_call(ag__.ld(step_function), (ag__.ld(self), ag__.ld(iterator)), None, fscope)\nValueError: in user code:\n\n    File \"c:\\Users\\AndrÃ¨s DLR\\AppData\\Local\\Programs\\Python\\Python310\\lib\\site-packages\\keras\\src\\engine\\training.py\", line 1338, in train_function  *\n        return step_function(self, iterator)\n    File \"c:\\Users\\AndrÃ¨s DLR\\AppData\\Local\\Programs\\Python\\Python310\\lib\\site-packages\\keras\\src\\engine\\training.py\", line 1322, in step_function  **\n        outputs = model.distribute_strategy.run(run_step, args=(data,))\n    File \"c:\\Users\\AndrÃ¨s DLR\\AppData\\Local\\Programs\\Python\\Python310\\lib\\site-packages\\keras\\src\\engine\\training.py\", line 1303, in run_step  **\n        outputs = model.train_step(data)\n    File \"c:\\Users\\AndrÃ¨s DLR\\AppData\\Local\\Programs\\Python\\Python310\\lib\\site-packages\\keras\\src\\engine\\training.py\", line 1080, in train_step\n        y_pred = self(x, training=True)\n    File \"c:\\Users\\AndrÃ¨s DLR\\AppData\\Local\\Programs\\Python\\Python310\\lib\\site-packages\\keras\\src\\utils\\traceback_utils.py\", line 70, in error_handler\n        raise e.with_traceback(filtered_tb) from None\n    File \"c:\\Users\\AndrÃ¨s DLR\\AppData\\Local\\Programs\\Python\\Python310\\lib\\site-packages\\keras\\src\\engine\\input_spec.py\", line 298, in assert_input_compatibility\n        raise ValueError(\n\n    ValueError: Input 0 of layer \"sequential_95\" is incompatible with the layer: expected shape=(None, 8), found shape=(10, 5)\n\n\n--------------------------------------------------------------------------------\n1 fits failed with the following error:\nTraceback (most recent call last):\n  File \"c:\\Users\\AndrÃ¨s DLR\\AppData\\Local\\Programs\\Python\\Python310\\lib\\site-packages\\sklearn\\model_selection\\_validation.py\", line 686, in _fit_and_score\n    estimator.fit(X_train, y_train, **fit_params)\n  File \"c:\\Users\\AndrÃ¨s DLR\\AppData\\Local\\Programs\\Python\\Python310\\lib\\site-packages\\scikeras\\wrappers.py\", line 1491, in fit\n    super().fit(X=X, y=y, sample_weight=sample_weight, **kwargs)\n  File \"c:\\Users\\AndrÃ¨s DLR\\AppData\\Local\\Programs\\Python\\Python310\\lib\\site-packages\\scikeras\\wrappers.py\", line 760, in fit\n    self._fit(\n  File \"c:\\Users\\AndrÃ¨s DLR\\AppData\\Local\\Programs\\Python\\Python310\\lib\\site-packages\\scikeras\\wrappers.py\", line 928, in _fit\n    self._fit_keras_model(\n  File \"c:\\Users\\AndrÃ¨s DLR\\AppData\\Local\\Programs\\Python\\Python310\\lib\\site-packages\\scikeras\\wrappers.py\", line 524, in _fit_keras_model\n    hist = self.model_.fit(x=X, y=y, **fit_args)\n  File \"c:\\Users\\AndrÃ¨s DLR\\AppData\\Local\\Programs\\Python\\Python310\\lib\\site-packages\\keras\\src\\utils\\traceback_utils.py\", line 70, in error_handler\n    raise e.with_traceback(filtered_tb) from None\n  File \"C:\\Users\\ANDRSD~1\\AppData\\Local\\Temp\\__autograph_generated_filethx4_r06.py\", line 15, in tf__train_function\n    retval_ = ag__.converted_call(ag__.ld(step_function), (ag__.ld(self), ag__.ld(iterator)), None, fscope)\nValueError: in user code:\n\n    File \"c:\\Users\\AndrÃ¨s DLR\\AppData\\Local\\Programs\\Python\\Python310\\lib\\site-packages\\keras\\src\\engine\\training.py\", line 1338, in train_function  *\n        return step_function(self, iterator)\n    File \"c:\\Users\\AndrÃ¨s DLR\\AppData\\Local\\Programs\\Python\\Python310\\lib\\site-packages\\keras\\src\\engine\\training.py\", line 1322, in step_function  **\n        outputs = model.distribute_strategy.run(run_step, args=(data,))\n    File \"c:\\Users\\AndrÃ¨s DLR\\AppData\\Local\\Programs\\Python\\Python310\\lib\\site-packages\\keras\\src\\engine\\training.py\", line 1303, in run_step  **\n        outputs = model.train_step(data)\n    File \"c:\\Users\\AndrÃ¨s DLR\\AppData\\Local\\Programs\\Python\\Python310\\lib\\site-packages\\keras\\src\\engine\\training.py\", line 1080, in train_step\n        y_pred = self(x, training=True)\n    File \"c:\\Users\\AndrÃ¨s DLR\\AppData\\Local\\Programs\\Python\\Python310\\lib\\site-packages\\keras\\src\\utils\\traceback_utils.py\", line 70, in error_handler\n        raise e.with_traceback(filtered_tb) from None\n    File \"c:\\Users\\AndrÃ¨s DLR\\AppData\\Local\\Programs\\Python\\Python310\\lib\\site-packages\\keras\\src\\engine\\input_spec.py\", line 298, in assert_input_compatibility\n        raise ValueError(\n\n    ValueError: Input 0 of layer \"sequential_96\" is incompatible with the layer: expected shape=(None, 8), found shape=(10, 5)\n\n\n--------------------------------------------------------------------------------\n1 fits failed with the following error:\nTraceback (most recent call last):\n  File \"c:\\Users\\AndrÃ¨s DLR\\AppData\\Local\\Programs\\Python\\Python310\\lib\\site-packages\\sklearn\\model_selection\\_validation.py\", line 686, in _fit_and_score\n    estimator.fit(X_train, y_train, **fit_params)\n  File \"c:\\Users\\AndrÃ¨s DLR\\AppData\\Local\\Programs\\Python\\Python310\\lib\\site-packages\\scikeras\\wrappers.py\", line 1491, in fit\n    super().fit(X=X, y=y, sample_weight=sample_weight, **kwargs)\n  File \"c:\\Users\\AndrÃ¨s DLR\\AppData\\Local\\Programs\\Python\\Python310\\lib\\site-packages\\scikeras\\wrappers.py\", line 760, in fit\n    self._fit(\n  File \"c:\\Users\\AndrÃ¨s DLR\\AppData\\Local\\Programs\\Python\\Python310\\lib\\site-packages\\scikeras\\wrappers.py\", line 928, in _fit\n    self._fit_keras_model(\n  File \"c:\\Users\\AndrÃ¨s DLR\\AppData\\Local\\Programs\\Python\\Python310\\lib\\site-packages\\scikeras\\wrappers.py\", line 524, in _fit_keras_model\n    hist = self.model_.fit(x=X, y=y, **fit_args)\n  File \"c:\\Users\\AndrÃ¨s DLR\\AppData\\Local\\Programs\\Python\\Python310\\lib\\site-packages\\keras\\src\\utils\\traceback_utils.py\", line 70, in error_handler\n    raise e.with_traceback(filtered_tb) from None\n  File \"C:\\Users\\ANDRSD~1\\AppData\\Local\\Temp\\__autograph_generated_filethx4_r06.py\", line 15, in tf__train_function\n    retval_ = ag__.converted_call(ag__.ld(step_function), (ag__.ld(self), ag__.ld(iterator)), None, fscope)\nValueError: in user code:\n\n    File \"c:\\Users\\AndrÃ¨s DLR\\AppData\\Local\\Programs\\Python\\Python310\\lib\\site-packages\\keras\\src\\engine\\training.py\", line 1338, in train_function  *\n        return step_function(self, iterator)\n    File \"c:\\Users\\AndrÃ¨s DLR\\AppData\\Local\\Programs\\Python\\Python310\\lib\\site-packages\\keras\\src\\engine\\training.py\", line 1322, in step_function  **\n        outputs = model.distribute_strategy.run(run_step, args=(data,))\n    File \"c:\\Users\\AndrÃ¨s DLR\\AppData\\Local\\Programs\\Python\\Python310\\lib\\site-packages\\keras\\src\\engine\\training.py\", line 1303, in run_step  **\n        outputs = model.train_step(data)\n    File \"c:\\Users\\AndrÃ¨s DLR\\AppData\\Local\\Programs\\Python\\Python310\\lib\\site-packages\\keras\\src\\engine\\training.py\", line 1080, in train_step\n        y_pred = self(x, training=True)\n    File \"c:\\Users\\AndrÃ¨s DLR\\AppData\\Local\\Programs\\Python\\Python310\\lib\\site-packages\\keras\\src\\utils\\traceback_utils.py\", line 70, in error_handler\n        raise e.with_traceback(filtered_tb) from None\n    File \"c:\\Users\\AndrÃ¨s DLR\\AppData\\Local\\Programs\\Python\\Python310\\lib\\site-packages\\keras\\src\\engine\\input_spec.py\", line 298, in assert_input_compatibility\n        raise ValueError(\n\n    ValueError: Input 0 of layer \"sequential_97\" is incompatible with the layer: expected shape=(None, 8), found shape=(10, 5)\n\n\n--------------------------------------------------------------------------------\n1 fits failed with the following error:\nTraceback (most recent call last):\n  File \"c:\\Users\\AndrÃ¨s DLR\\AppData\\Local\\Programs\\Python\\Python310\\lib\\site-packages\\sklearn\\model_selection\\_validation.py\", line 686, in _fit_and_score\n    estimator.fit(X_train, y_train, **fit_params)\n  File \"c:\\Users\\AndrÃ¨s DLR\\AppData\\Local\\Programs\\Python\\Python310\\lib\\site-packages\\scikeras\\wrappers.py\", line 1491, in fit\n    super().fit(X=X, y=y, sample_weight=sample_weight, **kwargs)\n  File \"c:\\Users\\AndrÃ¨s DLR\\AppData\\Local\\Programs\\Python\\Python310\\lib\\site-packages\\scikeras\\wrappers.py\", line 760, in fit\n    self._fit(\n  File \"c:\\Users\\AndrÃ¨s DLR\\AppData\\Local\\Programs\\Python\\Python310\\lib\\site-packages\\scikeras\\wrappers.py\", line 928, in _fit\n    self._fit_keras_model(\n  File \"c:\\Users\\AndrÃ¨s DLR\\AppData\\Local\\Programs\\Python\\Python310\\lib\\site-packages\\scikeras\\wrappers.py\", line 524, in _fit_keras_model\n    hist = self.model_.fit(x=X, y=y, **fit_args)\n  File \"c:\\Users\\AndrÃ¨s DLR\\AppData\\Local\\Programs\\Python\\Python310\\lib\\site-packages\\keras\\src\\utils\\traceback_utils.py\", line 70, in error_handler\n    raise e.with_traceback(filtered_tb) from None\n  File \"C:\\Users\\ANDRSD~1\\AppData\\Local\\Temp\\__autograph_generated_filethx4_r06.py\", line 15, in tf__train_function\n    retval_ = ag__.converted_call(ag__.ld(step_function), (ag__.ld(self), ag__.ld(iterator)), None, fscope)\nValueError: in user code:\n\n    File \"c:\\Users\\AndrÃ¨s DLR\\AppData\\Local\\Programs\\Python\\Python310\\lib\\site-packages\\keras\\src\\engine\\training.py\", line 1338, in train_function  *\n        return step_function(self, iterator)\n    File \"c:\\Users\\AndrÃ¨s DLR\\AppData\\Local\\Programs\\Python\\Python310\\lib\\site-packages\\keras\\src\\engine\\training.py\", line 1322, in step_function  **\n        outputs = model.distribute_strategy.run(run_step, args=(data,))\n    File \"c:\\Users\\AndrÃ¨s DLR\\AppData\\Local\\Programs\\Python\\Python310\\lib\\site-packages\\keras\\src\\engine\\training.py\", line 1303, in run_step  **\n        outputs = model.train_step(data)\n    File \"c:\\Users\\AndrÃ¨s DLR\\AppData\\Local\\Programs\\Python\\Python310\\lib\\site-packages\\keras\\src\\engine\\training.py\", line 1080, in train_step\n        y_pred = self(x, training=True)\n    File \"c:\\Users\\AndrÃ¨s DLR\\AppData\\Local\\Programs\\Python\\Python310\\lib\\site-packages\\keras\\src\\utils\\traceback_utils.py\", line 70, in error_handler\n        raise e.with_traceback(filtered_tb) from None\n    File \"c:\\Users\\AndrÃ¨s DLR\\AppData\\Local\\Programs\\Python\\Python310\\lib\\site-packages\\keras\\src\\engine\\input_spec.py\", line 298, in assert_input_compatibility\n        raise ValueError(\n\n    ValueError: Input 0 of layer \"sequential_98\" is incompatible with the layer: expected shape=(None, 8), found shape=(10, 5)\n\n\n--------------------------------------------------------------------------------\n1 fits failed with the following error:\nTraceback (most recent call last):\n  File \"c:\\Users\\AndrÃ¨s DLR\\AppData\\Local\\Programs\\Python\\Python310\\lib\\site-packages\\sklearn\\model_selection\\_validation.py\", line 686, in _fit_and_score\n    estimator.fit(X_train, y_train, **fit_params)\n  File \"c:\\Users\\AndrÃ¨s DLR\\AppData\\Local\\Programs\\Python\\Python310\\lib\\site-packages\\scikeras\\wrappers.py\", line 1491, in fit\n    super().fit(X=X, y=y, sample_weight=sample_weight, **kwargs)\n  File \"c:\\Users\\AndrÃ¨s DLR\\AppData\\Local\\Programs\\Python\\Python310\\lib\\site-packages\\scikeras\\wrappers.py\", line 760, in fit\n    self._fit(\n  File \"c:\\Users\\AndrÃ¨s DLR\\AppData\\Local\\Programs\\Python\\Python310\\lib\\site-packages\\scikeras\\wrappers.py\", line 928, in _fit\n    self._fit_keras_model(\n  File \"c:\\Users\\AndrÃ¨s DLR\\AppData\\Local\\Programs\\Python\\Python310\\lib\\site-packages\\scikeras\\wrappers.py\", line 524, in _fit_keras_model\n    hist = self.model_.fit(x=X, y=y, **fit_args)\n  File \"c:\\Users\\AndrÃ¨s DLR\\AppData\\Local\\Programs\\Python\\Python310\\lib\\site-packages\\keras\\src\\utils\\traceback_utils.py\", line 70, in error_handler\n    raise e.with_traceback(filtered_tb) from None\n  File \"C:\\Users\\ANDRSD~1\\AppData\\Local\\Temp\\__autograph_generated_filethx4_r06.py\", line 15, in tf__train_function\n    retval_ = ag__.converted_call(ag__.ld(step_function), (ag__.ld(self), ag__.ld(iterator)), None, fscope)\nValueError: in user code:\n\n    File \"c:\\Users\\AndrÃ¨s DLR\\AppData\\Local\\Programs\\Python\\Python310\\lib\\site-packages\\keras\\src\\engine\\training.py\", line 1338, in train_function  *\n        return step_function(self, iterator)\n    File \"c:\\Users\\AndrÃ¨s DLR\\AppData\\Local\\Programs\\Python\\Python310\\lib\\site-packages\\keras\\src\\engine\\training.py\", line 1322, in step_function  **\n        outputs = model.distribute_strategy.run(run_step, args=(data,))\n    File \"c:\\Users\\AndrÃ¨s DLR\\AppData\\Local\\Programs\\Python\\Python310\\lib\\site-packages\\keras\\src\\engine\\training.py\", line 1303, in run_step  **\n        outputs = model.train_step(data)\n    File \"c:\\Users\\AndrÃ¨s DLR\\AppData\\Local\\Programs\\Python\\Python310\\lib\\site-packages\\keras\\src\\engine\\training.py\", line 1080, in train_step\n        y_pred = self(x, training=True)\n    File \"c:\\Users\\AndrÃ¨s DLR\\AppData\\Local\\Programs\\Python\\Python310\\lib\\site-packages\\keras\\src\\utils\\traceback_utils.py\", line 70, in error_handler\n        raise e.with_traceback(filtered_tb) from None\n    File \"c:\\Users\\AndrÃ¨s DLR\\AppData\\Local\\Programs\\Python\\Python310\\lib\\site-packages\\keras\\src\\engine\\input_spec.py\", line 298, in assert_input_compatibility\n        raise ValueError(\n\n    ValueError: Input 0 of layer \"sequential_99\" is incompatible with the layer: expected shape=(None, 8), found shape=(10, 5)\n\n\n--------------------------------------------------------------------------------\n1 fits failed with the following error:\nTraceback (most recent call last):\n  File \"c:\\Users\\AndrÃ¨s DLR\\AppData\\Local\\Programs\\Python\\Python310\\lib\\site-packages\\sklearn\\model_selection\\_validation.py\", line 686, in _fit_and_score\n    estimator.fit(X_train, y_train, **fit_params)\n  File \"c:\\Users\\AndrÃ¨s DLR\\AppData\\Local\\Programs\\Python\\Python310\\lib\\site-packages\\scikeras\\wrappers.py\", line 1491, in fit\n    super().fit(X=X, y=y, sample_weight=sample_weight, **kwargs)\n  File \"c:\\Users\\AndrÃ¨s DLR\\AppData\\Local\\Programs\\Python\\Python310\\lib\\site-packages\\scikeras\\wrappers.py\", line 760, in fit\n    self._fit(\n  File \"c:\\Users\\AndrÃ¨s DLR\\AppData\\Local\\Programs\\Python\\Python310\\lib\\site-packages\\scikeras\\wrappers.py\", line 928, in _fit\n    self._fit_keras_model(\n  File \"c:\\Users\\AndrÃ¨s DLR\\AppData\\Local\\Programs\\Python\\Python310\\lib\\site-packages\\scikeras\\wrappers.py\", line 524, in _fit_keras_model\n    hist = self.model_.fit(x=X, y=y, **fit_args)\n  File \"c:\\Users\\AndrÃ¨s DLR\\AppData\\Local\\Programs\\Python\\Python310\\lib\\site-packages\\keras\\src\\utils\\traceback_utils.py\", line 70, in error_handler\n    raise e.with_traceback(filtered_tb) from None\n  File \"C:\\Users\\ANDRSD~1\\AppData\\Local\\Temp\\__autograph_generated_filethx4_r06.py\", line 15, in tf__train_function\n    retval_ = ag__.converted_call(ag__.ld(step_function), (ag__.ld(self), ag__.ld(iterator)), None, fscope)\nValueError: in user code:\n\n    File \"c:\\Users\\AndrÃ¨s DLR\\AppData\\Local\\Programs\\Python\\Python310\\lib\\site-packages\\keras\\src\\engine\\training.py\", line 1338, in train_function  *\n        return step_function(self, iterator)\n    File \"c:\\Users\\AndrÃ¨s DLR\\AppData\\Local\\Programs\\Python\\Python310\\lib\\site-packages\\keras\\src\\engine\\training.py\", line 1322, in step_function  **\n        outputs = model.distribute_strategy.run(run_step, args=(data,))\n    File \"c:\\Users\\AndrÃ¨s DLR\\AppData\\Local\\Programs\\Python\\Python310\\lib\\site-packages\\keras\\src\\engine\\training.py\", line 1303, in run_step  **\n        outputs = model.train_step(data)\n    File \"c:\\Users\\AndrÃ¨s DLR\\AppData\\Local\\Programs\\Python\\Python310\\lib\\site-packages\\keras\\src\\engine\\training.py\", line 1080, in train_step\n        y_pred = self(x, training=True)\n    File \"c:\\Users\\AndrÃ¨s DLR\\AppData\\Local\\Programs\\Python\\Python310\\lib\\site-packages\\keras\\src\\utils\\traceback_utils.py\", line 70, in error_handler\n        raise e.with_traceback(filtered_tb) from None\n    File \"c:\\Users\\AndrÃ¨s DLR\\AppData\\Local\\Programs\\Python\\Python310\\lib\\site-packages\\keras\\src\\engine\\input_spec.py\", line 298, in assert_input_compatibility\n        raise ValueError(\n\n    ValueError: Input 0 of layer \"sequential_100\" is incompatible with the layer: expected shape=(None, 8), found shape=(10, 5)\n\n\n--------------------------------------------------------------------------------\n1 fits failed with the following error:\nTraceback (most recent call last):\n  File \"c:\\Users\\AndrÃ¨s DLR\\AppData\\Local\\Programs\\Python\\Python310\\lib\\site-packages\\sklearn\\model_selection\\_validation.py\", line 686, in _fit_and_score\n    estimator.fit(X_train, y_train, **fit_params)\n  File \"c:\\Users\\AndrÃ¨s DLR\\AppData\\Local\\Programs\\Python\\Python310\\lib\\site-packages\\scikeras\\wrappers.py\", line 1491, in fit\n    super().fit(X=X, y=y, sample_weight=sample_weight, **kwargs)\n  File \"c:\\Users\\AndrÃ¨s DLR\\AppData\\Local\\Programs\\Python\\Python310\\lib\\site-packages\\scikeras\\wrappers.py\", line 760, in fit\n    self._fit(\n  File \"c:\\Users\\AndrÃ¨s DLR\\AppData\\Local\\Programs\\Python\\Python310\\lib\\site-packages\\scikeras\\wrappers.py\", line 928, in _fit\n    self._fit_keras_model(\n  File \"c:\\Users\\AndrÃ¨s DLR\\AppData\\Local\\Programs\\Python\\Python310\\lib\\site-packages\\scikeras\\wrappers.py\", line 524, in _fit_keras_model\n    hist = self.model_.fit(x=X, y=y, **fit_args)\n  File \"c:\\Users\\AndrÃ¨s DLR\\AppData\\Local\\Programs\\Python\\Python310\\lib\\site-packages\\keras\\src\\utils\\traceback_utils.py\", line 70, in error_handler\n    raise e.with_traceback(filtered_tb) from None\n  File \"C:\\Users\\ANDRSD~1\\AppData\\Local\\Temp\\__autograph_generated_filethx4_r06.py\", line 15, in tf__train_function\n    retval_ = ag__.converted_call(ag__.ld(step_function), (ag__.ld(self), ag__.ld(iterator)), None, fscope)\nValueError: in user code:\n\n    File \"c:\\Users\\AndrÃ¨s DLR\\AppData\\Local\\Programs\\Python\\Python310\\lib\\site-packages\\keras\\src\\engine\\training.py\", line 1338, in train_function  *\n        return step_function(self, iterator)\n    File \"c:\\Users\\AndrÃ¨s DLR\\AppData\\Local\\Programs\\Python\\Python310\\lib\\site-packages\\keras\\src\\engine\\training.py\", line 1322, in step_function  **\n        outputs = model.distribute_strategy.run(run_step, args=(data,))\n    File \"c:\\Users\\AndrÃ¨s DLR\\AppData\\Local\\Programs\\Python\\Python310\\lib\\site-packages\\keras\\src\\engine\\training.py\", line 1303, in run_step  **\n        outputs = model.train_step(data)\n    File \"c:\\Users\\AndrÃ¨s DLR\\AppData\\Local\\Programs\\Python\\Python310\\lib\\site-packages\\keras\\src\\engine\\training.py\", line 1080, in train_step\n        y_pred = self(x, training=True)\n    File \"c:\\Users\\AndrÃ¨s DLR\\AppData\\Local\\Programs\\Python\\Python310\\lib\\site-packages\\keras\\src\\utils\\traceback_utils.py\", line 70, in error_handler\n        raise e.with_traceback(filtered_tb) from None\n    File \"c:\\Users\\AndrÃ¨s DLR\\AppData\\Local\\Programs\\Python\\Python310\\lib\\site-packages\\keras\\src\\engine\\input_spec.py\", line 298, in assert_input_compatibility\n        raise ValueError(\n\n    ValueError: Input 0 of layer \"sequential_101\" is incompatible with the layer: expected shape=(None, 8), found shape=(10, 5)\n\n\n--------------------------------------------------------------------------------\n1 fits failed with the following error:\nTraceback (most recent call last):\n  File \"c:\\Users\\AndrÃ¨s DLR\\AppData\\Local\\Programs\\Python\\Python310\\lib\\site-packages\\sklearn\\model_selection\\_validation.py\", line 686, in _fit_and_score\n    estimator.fit(X_train, y_train, **fit_params)\n  File \"c:\\Users\\AndrÃ¨s DLR\\AppData\\Local\\Programs\\Python\\Python310\\lib\\site-packages\\scikeras\\wrappers.py\", line 1491, in fit\n    super().fit(X=X, y=y, sample_weight=sample_weight, **kwargs)\n  File \"c:\\Users\\AndrÃ¨s DLR\\AppData\\Local\\Programs\\Python\\Python310\\lib\\site-packages\\scikeras\\wrappers.py\", line 760, in fit\n    self._fit(\n  File \"c:\\Users\\AndrÃ¨s DLR\\AppData\\Local\\Programs\\Python\\Python310\\lib\\site-packages\\scikeras\\wrappers.py\", line 928, in _fit\n    self._fit_keras_model(\n  File \"c:\\Users\\AndrÃ¨s DLR\\AppData\\Local\\Programs\\Python\\Python310\\lib\\site-packages\\scikeras\\wrappers.py\", line 524, in _fit_keras_model\n    hist = self.model_.fit(x=X, y=y, **fit_args)\n  File \"c:\\Users\\AndrÃ¨s DLR\\AppData\\Local\\Programs\\Python\\Python310\\lib\\site-packages\\keras\\src\\utils\\traceback_utils.py\", line 70, in error_handler\n    raise e.with_traceback(filtered_tb) from None\n  File \"C:\\Users\\ANDRSD~1\\AppData\\Local\\Temp\\__autograph_generated_filethx4_r06.py\", line 15, in tf__train_function\n    retval_ = ag__.converted_call(ag__.ld(step_function), (ag__.ld(self), ag__.ld(iterator)), None, fscope)\nValueError: in user code:\n\n    File \"c:\\Users\\AndrÃ¨s DLR\\AppData\\Local\\Programs\\Python\\Python310\\lib\\site-packages\\keras\\src\\engine\\training.py\", line 1338, in train_function  *\n        return step_function(self, iterator)\n    File \"c:\\Users\\AndrÃ¨s DLR\\AppData\\Local\\Programs\\Python\\Python310\\lib\\site-packages\\keras\\src\\engine\\training.py\", line 1322, in step_function  **\n        outputs = model.distribute_strategy.run(run_step, args=(data,))\n    File \"c:\\Users\\AndrÃ¨s DLR\\AppData\\Local\\Programs\\Python\\Python310\\lib\\site-packages\\keras\\src\\engine\\training.py\", line 1303, in run_step  **\n        outputs = model.train_step(data)\n    File \"c:\\Users\\AndrÃ¨s DLR\\AppData\\Local\\Programs\\Python\\Python310\\lib\\site-packages\\keras\\src\\engine\\training.py\", line 1080, in train_step\n        y_pred = self(x, training=True)\n    File \"c:\\Users\\AndrÃ¨s DLR\\AppData\\Local\\Programs\\Python\\Python310\\lib\\site-packages\\keras\\src\\utils\\traceback_utils.py\", line 70, in error_handler\n        raise e.with_traceback(filtered_tb) from None\n    File \"c:\\Users\\AndrÃ¨s DLR\\AppData\\Local\\Programs\\Python\\Python310\\lib\\site-packages\\keras\\src\\engine\\input_spec.py\", line 298, in assert_input_compatibility\n        raise ValueError(\n\n    ValueError: Input 0 of layer \"sequential_102\" is incompatible with the layer: expected shape=(None, 8), found shape=(10, 5)\n\n\n--------------------------------------------------------------------------------\n1 fits failed with the following error:\nTraceback (most recent call last):\n  File \"c:\\Users\\AndrÃ¨s DLR\\AppData\\Local\\Programs\\Python\\Python310\\lib\\site-packages\\sklearn\\model_selection\\_validation.py\", line 686, in _fit_and_score\n    estimator.fit(X_train, y_train, **fit_params)\n  File \"c:\\Users\\AndrÃ¨s DLR\\AppData\\Local\\Programs\\Python\\Python310\\lib\\site-packages\\scikeras\\wrappers.py\", line 1491, in fit\n    super().fit(X=X, y=y, sample_weight=sample_weight, **kwargs)\n  File \"c:\\Users\\AndrÃ¨s DLR\\AppData\\Local\\Programs\\Python\\Python310\\lib\\site-packages\\scikeras\\wrappers.py\", line 760, in fit\n    self._fit(\n  File \"c:\\Users\\AndrÃ¨s DLR\\AppData\\Local\\Programs\\Python\\Python310\\lib\\site-packages\\scikeras\\wrappers.py\", line 928, in _fit\n    self._fit_keras_model(\n  File \"c:\\Users\\AndrÃ¨s DLR\\AppData\\Local\\Programs\\Python\\Python310\\lib\\site-packages\\scikeras\\wrappers.py\", line 524, in _fit_keras_model\n    hist = self.model_.fit(x=X, y=y, **fit_args)\n  File \"c:\\Users\\AndrÃ¨s DLR\\AppData\\Local\\Programs\\Python\\Python310\\lib\\site-packages\\keras\\src\\utils\\traceback_utils.py\", line 70, in error_handler\n    raise e.with_traceback(filtered_tb) from None\n  File \"C:\\Users\\ANDRSD~1\\AppData\\Local\\Temp\\__autograph_generated_filethx4_r06.py\", line 15, in tf__train_function\n    retval_ = ag__.converted_call(ag__.ld(step_function), (ag__.ld(self), ag__.ld(iterator)), None, fscope)\nValueError: in user code:\n\n    File \"c:\\Users\\AndrÃ¨s DLR\\AppData\\Local\\Programs\\Python\\Python310\\lib\\site-packages\\keras\\src\\engine\\training.py\", line 1338, in train_function  *\n        return step_function(self, iterator)\n    File \"c:\\Users\\AndrÃ¨s DLR\\AppData\\Local\\Programs\\Python\\Python310\\lib\\site-packages\\keras\\src\\engine\\training.py\", line 1322, in step_function  **\n        outputs = model.distribute_strategy.run(run_step, args=(data,))\n    File \"c:\\Users\\AndrÃ¨s DLR\\AppData\\Local\\Programs\\Python\\Python310\\lib\\site-packages\\keras\\src\\engine\\training.py\", line 1303, in run_step  **\n        outputs = model.train_step(data)\n    File \"c:\\Users\\AndrÃ¨s DLR\\AppData\\Local\\Programs\\Python\\Python310\\lib\\site-packages\\keras\\src\\engine\\training.py\", line 1080, in train_step\n        y_pred = self(x, training=True)\n    File \"c:\\Users\\AndrÃ¨s DLR\\AppData\\Local\\Programs\\Python\\Python310\\lib\\site-packages\\keras\\src\\utils\\traceback_utils.py\", line 70, in error_handler\n        raise e.with_traceback(filtered_tb) from None\n    File \"c:\\Users\\AndrÃ¨s DLR\\AppData\\Local\\Programs\\Python\\Python310\\lib\\site-packages\\keras\\src\\engine\\input_spec.py\", line 298, in assert_input_compatibility\n        raise ValueError(\n\n    ValueError: Input 0 of layer \"sequential_103\" is incompatible with the layer: expected shape=(None, 8), found shape=(10, 5)\n\n",
     "output_type": "error",
     "traceback": [
      "\u001b[1;31m---------------------------------------------------------------------------\u001b[0m",
      "\u001b[1;31mValueError\u001b[0m                                Traceback (most recent call last)",
      "Cell \u001b[1;32mIn[38], line 2\u001b[0m\n\u001b[0;32m      1\u001b[0m grid \u001b[39m=\u001b[39m GridSearchCV(estimator\u001b[39m=\u001b[39mmodel, param_grid\u001b[39m=\u001b[39mparam_grid, n_jobs\u001b[39m=\u001b[39m\u001b[39m1\u001b[39m, cv\u001b[39m=\u001b[39m\u001b[39m3\u001b[39m)\n\u001b[1;32m----> 2\u001b[0m grid_result \u001b[39m=\u001b[39m grid\u001b[39m.\u001b[39;49mfit(X, Y)\n\u001b[0;32m      3\u001b[0m \u001b[39m# summarize results\u001b[39;00m\n\u001b[0;32m      4\u001b[0m \u001b[39mprint\u001b[39m(\u001b[39m\"\u001b[39m\u001b[39mBest: \u001b[39m\u001b[39m%f\u001b[39;00m\u001b[39m using \u001b[39m\u001b[39m%s\u001b[39;00m\u001b[39m\"\u001b[39m \u001b[39m%\u001b[39m (grid_result\u001b[39m.\u001b[39mbest_score_, grid_result\u001b[39m.\u001b[39mbest_params_))\n",
      "File \u001b[1;32mc:\\Users\\AndrÃ¨s DLR\\AppData\\Local\\Programs\\Python\\Python310\\lib\\site-packages\\sklearn\\model_selection\\_search.py:875\u001b[0m, in \u001b[0;36mBaseSearchCV.fit\u001b[1;34m(self, X, y, groups, **fit_params)\u001b[0m\n\u001b[0;32m    869\u001b[0m     results \u001b[39m=\u001b[39m \u001b[39mself\u001b[39m\u001b[39m.\u001b[39m_format_results(\n\u001b[0;32m    870\u001b[0m         all_candidate_params, n_splits, all_out, all_more_results\n\u001b[0;32m    871\u001b[0m     )\n\u001b[0;32m    873\u001b[0m     \u001b[39mreturn\u001b[39;00m results\n\u001b[1;32m--> 875\u001b[0m \u001b[39mself\u001b[39;49m\u001b[39m.\u001b[39;49m_run_search(evaluate_candidates)\n\u001b[0;32m    877\u001b[0m \u001b[39m# multimetric is determined here because in the case of a callable\u001b[39;00m\n\u001b[0;32m    878\u001b[0m \u001b[39m# self.scoring the return type is only known after calling\u001b[39;00m\n\u001b[0;32m    879\u001b[0m first_test_score \u001b[39m=\u001b[39m all_out[\u001b[39m0\u001b[39m][\u001b[39m\"\u001b[39m\u001b[39mtest_scores\u001b[39m\u001b[39m\"\u001b[39m]\n",
      "File \u001b[1;32mc:\\Users\\AndrÃ¨s DLR\\AppData\\Local\\Programs\\Python\\Python310\\lib\\site-packages\\sklearn\\model_selection\\_search.py:1389\u001b[0m, in \u001b[0;36mGridSearchCV._run_search\u001b[1;34m(self, evaluate_candidates)\u001b[0m\n\u001b[0;32m   1387\u001b[0m \u001b[39mdef\u001b[39;00m \u001b[39m_run_search\u001b[39m(\u001b[39mself\u001b[39m, evaluate_candidates):\n\u001b[0;32m   1388\u001b[0m \u001b[39m    \u001b[39m\u001b[39m\"\"\"Search all candidates in param_grid\"\"\"\u001b[39;00m\n\u001b[1;32m-> 1389\u001b[0m     evaluate_candidates(ParameterGrid(\u001b[39mself\u001b[39;49m\u001b[39m.\u001b[39;49mparam_grid))\n",
      "File \u001b[1;32mc:\\Users\\AndrÃ¨s DLR\\AppData\\Local\\Programs\\Python\\Python310\\lib\\site-packages\\sklearn\\model_selection\\_search.py:852\u001b[0m, in \u001b[0;36mBaseSearchCV.fit.<locals>.evaluate_candidates\u001b[1;34m(candidate_params, cv, more_results)\u001b[0m\n\u001b[0;32m    845\u001b[0m \u001b[39melif\u001b[39;00m \u001b[39mlen\u001b[39m(out) \u001b[39m!=\u001b[39m n_candidates \u001b[39m*\u001b[39m n_splits:\n\u001b[0;32m    846\u001b[0m     \u001b[39mraise\u001b[39;00m \u001b[39mValueError\u001b[39;00m(\n\u001b[0;32m    847\u001b[0m         \u001b[39m\"\u001b[39m\u001b[39mcv.split and cv.get_n_splits returned \u001b[39m\u001b[39m\"\u001b[39m\n\u001b[0;32m    848\u001b[0m         \u001b[39m\"\u001b[39m\u001b[39minconsistent results. Expected \u001b[39m\u001b[39m{}\u001b[39;00m\u001b[39m \u001b[39m\u001b[39m\"\u001b[39m\n\u001b[0;32m    849\u001b[0m         \u001b[39m\"\u001b[39m\u001b[39msplits, got \u001b[39m\u001b[39m{}\u001b[39;00m\u001b[39m\"\u001b[39m\u001b[39m.\u001b[39mformat(n_splits, \u001b[39mlen\u001b[39m(out) \u001b[39m/\u001b[39m\u001b[39m/\u001b[39m n_candidates)\n\u001b[0;32m    850\u001b[0m     )\n\u001b[1;32m--> 852\u001b[0m _warn_or_raise_about_fit_failures(out, \u001b[39mself\u001b[39;49m\u001b[39m.\u001b[39;49merror_score)\n\u001b[0;32m    854\u001b[0m \u001b[39m# For callable self.scoring, the return type is only know after\u001b[39;00m\n\u001b[0;32m    855\u001b[0m \u001b[39m# calling. If the return type is a dictionary, the error scores\u001b[39;00m\n\u001b[0;32m    856\u001b[0m \u001b[39m# can now be inserted with the correct key. The type checking\u001b[39;00m\n\u001b[0;32m    857\u001b[0m \u001b[39m# of out will be done in `_insert_error_scores`.\u001b[39;00m\n\u001b[0;32m    858\u001b[0m \u001b[39mif\u001b[39;00m callable(\u001b[39mself\u001b[39m\u001b[39m.\u001b[39mscoring):\n",
      "File \u001b[1;32mc:\\Users\\AndrÃ¨s DLR\\AppData\\Local\\Programs\\Python\\Python310\\lib\\site-packages\\sklearn\\model_selection\\_validation.py:367\u001b[0m, in \u001b[0;36m_warn_or_raise_about_fit_failures\u001b[1;34m(results, error_score)\u001b[0m\n\u001b[0;32m    360\u001b[0m \u001b[39mif\u001b[39;00m num_failed_fits \u001b[39m==\u001b[39m num_fits:\n\u001b[0;32m    361\u001b[0m     all_fits_failed_message \u001b[39m=\u001b[39m (\n\u001b[0;32m    362\u001b[0m         \u001b[39mf\u001b[39m\u001b[39m\"\u001b[39m\u001b[39m\\n\u001b[39;00m\u001b[39mAll the \u001b[39m\u001b[39m{\u001b[39;00mnum_fits\u001b[39m}\u001b[39;00m\u001b[39m fits failed.\u001b[39m\u001b[39m\\n\u001b[39;00m\u001b[39m\"\u001b[39m\n\u001b[0;32m    363\u001b[0m         \u001b[39m\"\u001b[39m\u001b[39mIt is very likely that your model is misconfigured.\u001b[39m\u001b[39m\\n\u001b[39;00m\u001b[39m\"\u001b[39m\n\u001b[0;32m    364\u001b[0m         \u001b[39m\"\u001b[39m\u001b[39mYou can try to debug the error by setting error_score=\u001b[39m\u001b[39m'\u001b[39m\u001b[39mraise\u001b[39m\u001b[39m'\u001b[39m\u001b[39m.\u001b[39m\u001b[39m\\n\u001b[39;00m\u001b[39m\\n\u001b[39;00m\u001b[39m\"\u001b[39m\n\u001b[0;32m    365\u001b[0m         \u001b[39mf\u001b[39m\u001b[39m\"\u001b[39m\u001b[39mBelow are more details about the failures:\u001b[39m\u001b[39m\\n\u001b[39;00m\u001b[39m{\u001b[39;00mfit_errors_summary\u001b[39m}\u001b[39;00m\u001b[39m\"\u001b[39m\n\u001b[0;32m    366\u001b[0m     )\n\u001b[1;32m--> 367\u001b[0m     \u001b[39mraise\u001b[39;00m \u001b[39mValueError\u001b[39;00m(all_fits_failed_message)\n\u001b[0;32m    369\u001b[0m \u001b[39melse\u001b[39;00m:\n\u001b[0;32m    370\u001b[0m     some_fits_failed_message \u001b[39m=\u001b[39m (\n\u001b[0;32m    371\u001b[0m         \u001b[39mf\u001b[39m\u001b[39m\"\u001b[39m\u001b[39m\\n\u001b[39;00m\u001b[39m{\u001b[39;00mnum_failed_fits\u001b[39m}\u001b[39;00m\u001b[39m fits failed out of a total of \u001b[39m\u001b[39m{\u001b[39;00mnum_fits\u001b[39m}\u001b[39;00m\u001b[39m.\u001b[39m\u001b[39m\\n\u001b[39;00m\u001b[39m\"\u001b[39m\n\u001b[0;32m    372\u001b[0m         \u001b[39m\"\u001b[39m\u001b[39mThe score on these train-test partitions for these parameters\u001b[39m\u001b[39m\"\u001b[39m\n\u001b[1;32m   (...)\u001b[0m\n\u001b[0;32m    376\u001b[0m         \u001b[39mf\u001b[39m\u001b[39m\"\u001b[39m\u001b[39mBelow are more details about the failures:\u001b[39m\u001b[39m\\n\u001b[39;00m\u001b[39m{\u001b[39;00mfit_errors_summary\u001b[39m}\u001b[39;00m\u001b[39m\"\u001b[39m\n\u001b[0;32m    377\u001b[0m     )\n",
      "\u001b[1;31mValueError\u001b[0m: \nAll the 21 fits failed.\nIt is very likely that your model is misconfigured.\nYou can try to debug the error by setting error_score='raise'.\n\nBelow are more details about the failures:\n--------------------------------------------------------------------------------\n1 fits failed with the following error:\nTraceback (most recent call last):\n  File \"c:\\Users\\AndrÃ¨s DLR\\AppData\\Local\\Programs\\Python\\Python310\\lib\\site-packages\\sklearn\\model_selection\\_validation.py\", line 686, in _fit_and_score\n    estimator.fit(X_train, y_train, **fit_params)\n  File \"c:\\Users\\AndrÃ¨s DLR\\AppData\\Local\\Programs\\Python\\Python310\\lib\\site-packages\\scikeras\\wrappers.py\", line 1491, in fit\n    super().fit(X=X, y=y, sample_weight=sample_weight, **kwargs)\n  File \"c:\\Users\\AndrÃ¨s DLR\\AppData\\Local\\Programs\\Python\\Python310\\lib\\site-packages\\scikeras\\wrappers.py\", line 760, in fit\n    self._fit(\n  File \"c:\\Users\\AndrÃ¨s DLR\\AppData\\Local\\Programs\\Python\\Python310\\lib\\site-packages\\scikeras\\wrappers.py\", line 928, in _fit\n    self._fit_keras_model(\n  File \"c:\\Users\\AndrÃ¨s DLR\\AppData\\Local\\Programs\\Python\\Python310\\lib\\site-packages\\scikeras\\wrappers.py\", line 524, in _fit_keras_model\n    hist = self.model_.fit(x=X, y=y, **fit_args)\n  File \"c:\\Users\\AndrÃ¨s DLR\\AppData\\Local\\Programs\\Python\\Python310\\lib\\site-packages\\keras\\src\\utils\\traceback_utils.py\", line 70, in error_handler\n    raise e.with_traceback(filtered_tb) from None\n  File \"C:\\Users\\ANDRSD~1\\AppData\\Local\\Temp\\__autograph_generated_filethx4_r06.py\", line 15, in tf__train_function\n    retval_ = ag__.converted_call(ag__.ld(step_function), (ag__.ld(self), ag__.ld(iterator)), None, fscope)\nValueError: in user code:\n\n    File \"c:\\Users\\AndrÃ¨s DLR\\AppData\\Local\\Programs\\Python\\Python310\\lib\\site-packages\\keras\\src\\engine\\training.py\", line 1338, in train_function  *\n        return step_function(self, iterator)\n    File \"c:\\Users\\AndrÃ¨s DLR\\AppData\\Local\\Programs\\Python\\Python310\\lib\\site-packages\\keras\\src\\engine\\training.py\", line 1322, in step_function  **\n        outputs = model.distribute_strategy.run(run_step, args=(data,))\n    File \"c:\\Users\\AndrÃ¨s DLR\\AppData\\Local\\Programs\\Python\\Python310\\lib\\site-packages\\keras\\src\\engine\\training.py\", line 1303, in run_step  **\n        outputs = model.train_step(data)\n    File \"c:\\Users\\AndrÃ¨s DLR\\AppData\\Local\\Programs\\Python\\Python310\\lib\\site-packages\\keras\\src\\engine\\training.py\", line 1080, in train_step\n        y_pred = self(x, training=True)\n    File \"c:\\Users\\AndrÃ¨s DLR\\AppData\\Local\\Programs\\Python\\Python310\\lib\\site-packages\\keras\\src\\utils\\traceback_utils.py\", line 70, in error_handler\n        raise e.with_traceback(filtered_tb) from None\n    File \"c:\\Users\\AndrÃ¨s DLR\\AppData\\Local\\Programs\\Python\\Python310\\lib\\site-packages\\keras\\src\\engine\\input_spec.py\", line 298, in assert_input_compatibility\n        raise ValueError(\n\n    ValueError: Input 0 of layer \"sequential_83\" is incompatible with the layer: expected shape=(None, 8), found shape=(10, 5)\n\n\n--------------------------------------------------------------------------------\n1 fits failed with the following error:\nTraceback (most recent call last):\n  File \"c:\\Users\\AndrÃ¨s DLR\\AppData\\Local\\Programs\\Python\\Python310\\lib\\site-packages\\sklearn\\model_selection\\_validation.py\", line 686, in _fit_and_score\n    estimator.fit(X_train, y_train, **fit_params)\n  File \"c:\\Users\\AndrÃ¨s DLR\\AppData\\Local\\Programs\\Python\\Python310\\lib\\site-packages\\scikeras\\wrappers.py\", line 1491, in fit\n    super().fit(X=X, y=y, sample_weight=sample_weight, **kwargs)\n  File \"c:\\Users\\AndrÃ¨s DLR\\AppData\\Local\\Programs\\Python\\Python310\\lib\\site-packages\\scikeras\\wrappers.py\", line 760, in fit\n    self._fit(\n  File \"c:\\Users\\AndrÃ¨s DLR\\AppData\\Local\\Programs\\Python\\Python310\\lib\\site-packages\\scikeras\\wrappers.py\", line 928, in _fit\n    self._fit_keras_model(\n  File \"c:\\Users\\AndrÃ¨s DLR\\AppData\\Local\\Programs\\Python\\Python310\\lib\\site-packages\\scikeras\\wrappers.py\", line 524, in _fit_keras_model\n    hist = self.model_.fit(x=X, y=y, **fit_args)\n  File \"c:\\Users\\AndrÃ¨s DLR\\AppData\\Local\\Programs\\Python\\Python310\\lib\\site-packages\\keras\\src\\utils\\traceback_utils.py\", line 70, in error_handler\n    raise e.with_traceback(filtered_tb) from None\n  File \"C:\\Users\\ANDRSD~1\\AppData\\Local\\Temp\\__autograph_generated_filethx4_r06.py\", line 15, in tf__train_function\n    retval_ = ag__.converted_call(ag__.ld(step_function), (ag__.ld(self), ag__.ld(iterator)), None, fscope)\nValueError: in user code:\n\n    File \"c:\\Users\\AndrÃ¨s DLR\\AppData\\Local\\Programs\\Python\\Python310\\lib\\site-packages\\keras\\src\\engine\\training.py\", line 1338, in train_function  *\n        return step_function(self, iterator)\n    File \"c:\\Users\\AndrÃ¨s DLR\\AppData\\Local\\Programs\\Python\\Python310\\lib\\site-packages\\keras\\src\\engine\\training.py\", line 1322, in step_function  **\n        outputs = model.distribute_strategy.run(run_step, args=(data,))\n    File \"c:\\Users\\AndrÃ¨s DLR\\AppData\\Local\\Programs\\Python\\Python310\\lib\\site-packages\\keras\\src\\engine\\training.py\", line 1303, in run_step  **\n        outputs = model.train_step(data)\n    File \"c:\\Users\\AndrÃ¨s DLR\\AppData\\Local\\Programs\\Python\\Python310\\lib\\site-packages\\keras\\src\\engine\\training.py\", line 1080, in train_step\n        y_pred = self(x, training=True)\n    File \"c:\\Users\\AndrÃ¨s DLR\\AppData\\Local\\Programs\\Python\\Python310\\lib\\site-packages\\keras\\src\\utils\\traceback_utils.py\", line 70, in error_handler\n        raise e.with_traceback(filtered_tb) from None\n    File \"c:\\Users\\AndrÃ¨s DLR\\AppData\\Local\\Programs\\Python\\Python310\\lib\\site-packages\\keras\\src\\engine\\input_spec.py\", line 298, in assert_input_compatibility\n        raise ValueError(\n\n    ValueError: Input 0 of layer \"sequential_84\" is incompatible with the layer: expected shape=(None, 8), found shape=(10, 5)\n\n\n--------------------------------------------------------------------------------\n1 fits failed with the following error:\nTraceback (most recent call last):\n  File \"c:\\Users\\AndrÃ¨s DLR\\AppData\\Local\\Programs\\Python\\Python310\\lib\\site-packages\\sklearn\\model_selection\\_validation.py\", line 686, in _fit_and_score\n    estimator.fit(X_train, y_train, **fit_params)\n  File \"c:\\Users\\AndrÃ¨s DLR\\AppData\\Local\\Programs\\Python\\Python310\\lib\\site-packages\\scikeras\\wrappers.py\", line 1491, in fit\n    super().fit(X=X, y=y, sample_weight=sample_weight, **kwargs)\n  File \"c:\\Users\\AndrÃ¨s DLR\\AppData\\Local\\Programs\\Python\\Python310\\lib\\site-packages\\scikeras\\wrappers.py\", line 760, in fit\n    self._fit(\n  File \"c:\\Users\\AndrÃ¨s DLR\\AppData\\Local\\Programs\\Python\\Python310\\lib\\site-packages\\scikeras\\wrappers.py\", line 928, in _fit\n    self._fit_keras_model(\n  File \"c:\\Users\\AndrÃ¨s DLR\\AppData\\Local\\Programs\\Python\\Python310\\lib\\site-packages\\scikeras\\wrappers.py\", line 524, in _fit_keras_model\n    hist = self.model_.fit(x=X, y=y, **fit_args)\n  File \"c:\\Users\\AndrÃ¨s DLR\\AppData\\Local\\Programs\\Python\\Python310\\lib\\site-packages\\keras\\src\\utils\\traceback_utils.py\", line 70, in error_handler\n    raise e.with_traceback(filtered_tb) from None\n  File \"C:\\Users\\ANDRSD~1\\AppData\\Local\\Temp\\__autograph_generated_filethx4_r06.py\", line 15, in tf__train_function\n    retval_ = ag__.converted_call(ag__.ld(step_function), (ag__.ld(self), ag__.ld(iterator)), None, fscope)\nValueError: in user code:\n\n    File \"c:\\Users\\AndrÃ¨s DLR\\AppData\\Local\\Programs\\Python\\Python310\\lib\\site-packages\\keras\\src\\engine\\training.py\", line 1338, in train_function  *\n        return step_function(self, iterator)\n    File \"c:\\Users\\AndrÃ¨s DLR\\AppData\\Local\\Programs\\Python\\Python310\\lib\\site-packages\\keras\\src\\engine\\training.py\", line 1322, in step_function  **\n        outputs = model.distribute_strategy.run(run_step, args=(data,))\n    File \"c:\\Users\\AndrÃ¨s DLR\\AppData\\Local\\Programs\\Python\\Python310\\lib\\site-packages\\keras\\src\\engine\\training.py\", line 1303, in run_step  **\n        outputs = model.train_step(data)\n    File \"c:\\Users\\AndrÃ¨s DLR\\AppData\\Local\\Programs\\Python\\Python310\\lib\\site-packages\\keras\\src\\engine\\training.py\", line 1080, in train_step\n        y_pred = self(x, training=True)\n    File \"c:\\Users\\AndrÃ¨s DLR\\AppData\\Local\\Programs\\Python\\Python310\\lib\\site-packages\\keras\\src\\utils\\traceback_utils.py\", line 70, in error_handler\n        raise e.with_traceback(filtered_tb) from None\n    File \"c:\\Users\\AndrÃ¨s DLR\\AppData\\Local\\Programs\\Python\\Python310\\lib\\site-packages\\keras\\src\\engine\\input_spec.py\", line 298, in assert_input_compatibility\n        raise ValueError(\n\n    ValueError: Input 0 of layer \"sequential_85\" is incompatible with the layer: expected shape=(None, 8), found shape=(10, 5)\n\n\n--------------------------------------------------------------------------------\n1 fits failed with the following error:\nTraceback (most recent call last):\n  File \"c:\\Users\\AndrÃ¨s DLR\\AppData\\Local\\Programs\\Python\\Python310\\lib\\site-packages\\sklearn\\model_selection\\_validation.py\", line 686, in _fit_and_score\n    estimator.fit(X_train, y_train, **fit_params)\n  File \"c:\\Users\\AndrÃ¨s DLR\\AppData\\Local\\Programs\\Python\\Python310\\lib\\site-packages\\scikeras\\wrappers.py\", line 1491, in fit\n    super().fit(X=X, y=y, sample_weight=sample_weight, **kwargs)\n  File \"c:\\Users\\AndrÃ¨s DLR\\AppData\\Local\\Programs\\Python\\Python310\\lib\\site-packages\\scikeras\\wrappers.py\", line 760, in fit\n    self._fit(\n  File \"c:\\Users\\AndrÃ¨s DLR\\AppData\\Local\\Programs\\Python\\Python310\\lib\\site-packages\\scikeras\\wrappers.py\", line 928, in _fit\n    self._fit_keras_model(\n  File \"c:\\Users\\AndrÃ¨s DLR\\AppData\\Local\\Programs\\Python\\Python310\\lib\\site-packages\\scikeras\\wrappers.py\", line 524, in _fit_keras_model\n    hist = self.model_.fit(x=X, y=y, **fit_args)\n  File \"c:\\Users\\AndrÃ¨s DLR\\AppData\\Local\\Programs\\Python\\Python310\\lib\\site-packages\\keras\\src\\utils\\traceback_utils.py\", line 70, in error_handler\n    raise e.with_traceback(filtered_tb) from None\n  File \"C:\\Users\\ANDRSD~1\\AppData\\Local\\Temp\\__autograph_generated_filethx4_r06.py\", line 15, in tf__train_function\n    retval_ = ag__.converted_call(ag__.ld(step_function), (ag__.ld(self), ag__.ld(iterator)), None, fscope)\nValueError: in user code:\n\n    File \"c:\\Users\\AndrÃ¨s DLR\\AppData\\Local\\Programs\\Python\\Python310\\lib\\site-packages\\keras\\src\\engine\\training.py\", line 1338, in train_function  *\n        return step_function(self, iterator)\n    File \"c:\\Users\\AndrÃ¨s DLR\\AppData\\Local\\Programs\\Python\\Python310\\lib\\site-packages\\keras\\src\\engine\\training.py\", line 1322, in step_function  **\n        outputs = model.distribute_strategy.run(run_step, args=(data,))\n    File \"c:\\Users\\AndrÃ¨s DLR\\AppData\\Local\\Programs\\Python\\Python310\\lib\\site-packages\\keras\\src\\engine\\training.py\", line 1303, in run_step  **\n        outputs = model.train_step(data)\n    File \"c:\\Users\\AndrÃ¨s DLR\\AppData\\Local\\Programs\\Python\\Python310\\lib\\site-packages\\keras\\src\\engine\\training.py\", line 1080, in train_step\n        y_pred = self(x, training=True)\n    File \"c:\\Users\\AndrÃ¨s DLR\\AppData\\Local\\Programs\\Python\\Python310\\lib\\site-packages\\keras\\src\\utils\\traceback_utils.py\", line 70, in error_handler\n        raise e.with_traceback(filtered_tb) from None\n    File \"c:\\Users\\AndrÃ¨s DLR\\AppData\\Local\\Programs\\Python\\Python310\\lib\\site-packages\\keras\\src\\engine\\input_spec.py\", line 298, in assert_input_compatibility\n        raise ValueError(\n\n    ValueError: Input 0 of layer \"sequential_86\" is incompatible with the layer: expected shape=(None, 8), found shape=(10, 5)\n\n\n--------------------------------------------------------------------------------\n1 fits failed with the following error:\nTraceback (most recent call last):\n  File \"c:\\Users\\AndrÃ¨s DLR\\AppData\\Local\\Programs\\Python\\Python310\\lib\\site-packages\\sklearn\\model_selection\\_validation.py\", line 686, in _fit_and_score\n    estimator.fit(X_train, y_train, **fit_params)\n  File \"c:\\Users\\AndrÃ¨s DLR\\AppData\\Local\\Programs\\Python\\Python310\\lib\\site-packages\\scikeras\\wrappers.py\", line 1491, in fit\n    super().fit(X=X, y=y, sample_weight=sample_weight, **kwargs)\n  File \"c:\\Users\\AndrÃ¨s DLR\\AppData\\Local\\Programs\\Python\\Python310\\lib\\site-packages\\scikeras\\wrappers.py\", line 760, in fit\n    self._fit(\n  File \"c:\\Users\\AndrÃ¨s DLR\\AppData\\Local\\Programs\\Python\\Python310\\lib\\site-packages\\scikeras\\wrappers.py\", line 928, in _fit\n    self._fit_keras_model(\n  File \"c:\\Users\\AndrÃ¨s DLR\\AppData\\Local\\Programs\\Python\\Python310\\lib\\site-packages\\scikeras\\wrappers.py\", line 524, in _fit_keras_model\n    hist = self.model_.fit(x=X, y=y, **fit_args)\n  File \"c:\\Users\\AndrÃ¨s DLR\\AppData\\Local\\Programs\\Python\\Python310\\lib\\site-packages\\keras\\src\\utils\\traceback_utils.py\", line 70, in error_handler\n    raise e.with_traceback(filtered_tb) from None\n  File \"C:\\Users\\ANDRSD~1\\AppData\\Local\\Temp\\__autograph_generated_filethx4_r06.py\", line 15, in tf__train_function\n    retval_ = ag__.converted_call(ag__.ld(step_function), (ag__.ld(self), ag__.ld(iterator)), None, fscope)\nValueError: in user code:\n\n    File \"c:\\Users\\AndrÃ¨s DLR\\AppData\\Local\\Programs\\Python\\Python310\\lib\\site-packages\\keras\\src\\engine\\training.py\", line 1338, in train_function  *\n        return step_function(self, iterator)\n    File \"c:\\Users\\AndrÃ¨s DLR\\AppData\\Local\\Programs\\Python\\Python310\\lib\\site-packages\\keras\\src\\engine\\training.py\", line 1322, in step_function  **\n        outputs = model.distribute_strategy.run(run_step, args=(data,))\n    File \"c:\\Users\\AndrÃ¨s DLR\\AppData\\Local\\Programs\\Python\\Python310\\lib\\site-packages\\keras\\src\\engine\\training.py\", line 1303, in run_step  **\n        outputs = model.train_step(data)\n    File \"c:\\Users\\AndrÃ¨s DLR\\AppData\\Local\\Programs\\Python\\Python310\\lib\\site-packages\\keras\\src\\engine\\training.py\", line 1080, in train_step\n        y_pred = self(x, training=True)\n    File \"c:\\Users\\AndrÃ¨s DLR\\AppData\\Local\\Programs\\Python\\Python310\\lib\\site-packages\\keras\\src\\utils\\traceback_utils.py\", line 70, in error_handler\n        raise e.with_traceback(filtered_tb) from None\n    File \"c:\\Users\\AndrÃ¨s DLR\\AppData\\Local\\Programs\\Python\\Python310\\lib\\site-packages\\keras\\src\\engine\\input_spec.py\", line 298, in assert_input_compatibility\n        raise ValueError(\n\n    ValueError: Input 0 of layer \"sequential_87\" is incompatible with the layer: expected shape=(None, 8), found shape=(10, 5)\n\n\n--------------------------------------------------------------------------------\n1 fits failed with the following error:\nTraceback (most recent call last):\n  File \"c:\\Users\\AndrÃ¨s DLR\\AppData\\Local\\Programs\\Python\\Python310\\lib\\site-packages\\sklearn\\model_selection\\_validation.py\", line 686, in _fit_and_score\n    estimator.fit(X_train, y_train, **fit_params)\n  File \"c:\\Users\\AndrÃ¨s DLR\\AppData\\Local\\Programs\\Python\\Python310\\lib\\site-packages\\scikeras\\wrappers.py\", line 1491, in fit\n    super().fit(X=X, y=y, sample_weight=sample_weight, **kwargs)\n  File \"c:\\Users\\AndrÃ¨s DLR\\AppData\\Local\\Programs\\Python\\Python310\\lib\\site-packages\\scikeras\\wrappers.py\", line 760, in fit\n    self._fit(\n  File \"c:\\Users\\AndrÃ¨s DLR\\AppData\\Local\\Programs\\Python\\Python310\\lib\\site-packages\\scikeras\\wrappers.py\", line 928, in _fit\n    self._fit_keras_model(\n  File \"c:\\Users\\AndrÃ¨s DLR\\AppData\\Local\\Programs\\Python\\Python310\\lib\\site-packages\\scikeras\\wrappers.py\", line 524, in _fit_keras_model\n    hist = self.model_.fit(x=X, y=y, **fit_args)\n  File \"c:\\Users\\AndrÃ¨s DLR\\AppData\\Local\\Programs\\Python\\Python310\\lib\\site-packages\\keras\\src\\utils\\traceback_utils.py\", line 70, in error_handler\n    raise e.with_traceback(filtered_tb) from None\n  File \"C:\\Users\\ANDRSD~1\\AppData\\Local\\Temp\\__autograph_generated_filethx4_r06.py\", line 15, in tf__train_function\n    retval_ = ag__.converted_call(ag__.ld(step_function), (ag__.ld(self), ag__.ld(iterator)), None, fscope)\nValueError: in user code:\n\n    File \"c:\\Users\\AndrÃ¨s DLR\\AppData\\Local\\Programs\\Python\\Python310\\lib\\site-packages\\keras\\src\\engine\\training.py\", line 1338, in train_function  *\n        return step_function(self, iterator)\n    File \"c:\\Users\\AndrÃ¨s DLR\\AppData\\Local\\Programs\\Python\\Python310\\lib\\site-packages\\keras\\src\\engine\\training.py\", line 1322, in step_function  **\n        outputs = model.distribute_strategy.run(run_step, args=(data,))\n    File \"c:\\Users\\AndrÃ¨s DLR\\AppData\\Local\\Programs\\Python\\Python310\\lib\\site-packages\\keras\\src\\engine\\training.py\", line 1303, in run_step  **\n        outputs = model.train_step(data)\n    File \"c:\\Users\\AndrÃ¨s DLR\\AppData\\Local\\Programs\\Python\\Python310\\lib\\site-packages\\keras\\src\\engine\\training.py\", line 1080, in train_step\n        y_pred = self(x, training=True)\n    File \"c:\\Users\\AndrÃ¨s DLR\\AppData\\Local\\Programs\\Python\\Python310\\lib\\site-packages\\keras\\src\\utils\\traceback_utils.py\", line 70, in error_handler\n        raise e.with_traceback(filtered_tb) from None\n    File \"c:\\Users\\AndrÃ¨s DLR\\AppData\\Local\\Programs\\Python\\Python310\\lib\\site-packages\\keras\\src\\engine\\input_spec.py\", line 298, in assert_input_compatibility\n        raise ValueError(\n\n    ValueError: Input 0 of layer \"sequential_88\" is incompatible with the layer: expected shape=(None, 8), found shape=(10, 5)\n\n\n--------------------------------------------------------------------------------\n1 fits failed with the following error:\nTraceback (most recent call last):\n  File \"c:\\Users\\AndrÃ¨s DLR\\AppData\\Local\\Programs\\Python\\Python310\\lib\\site-packages\\sklearn\\model_selection\\_validation.py\", line 686, in _fit_and_score\n    estimator.fit(X_train, y_train, **fit_params)\n  File \"c:\\Users\\AndrÃ¨s DLR\\AppData\\Local\\Programs\\Python\\Python310\\lib\\site-packages\\scikeras\\wrappers.py\", line 1491, in fit\n    super().fit(X=X, y=y, sample_weight=sample_weight, **kwargs)\n  File \"c:\\Users\\AndrÃ¨s DLR\\AppData\\Local\\Programs\\Python\\Python310\\lib\\site-packages\\scikeras\\wrappers.py\", line 760, in fit\n    self._fit(\n  File \"c:\\Users\\AndrÃ¨s DLR\\AppData\\Local\\Programs\\Python\\Python310\\lib\\site-packages\\scikeras\\wrappers.py\", line 928, in _fit\n    self._fit_keras_model(\n  File \"c:\\Users\\AndrÃ¨s DLR\\AppData\\Local\\Programs\\Python\\Python310\\lib\\site-packages\\scikeras\\wrappers.py\", line 524, in _fit_keras_model\n    hist = self.model_.fit(x=X, y=y, **fit_args)\n  File \"c:\\Users\\AndrÃ¨s DLR\\AppData\\Local\\Programs\\Python\\Python310\\lib\\site-packages\\keras\\src\\utils\\traceback_utils.py\", line 70, in error_handler\n    raise e.with_traceback(filtered_tb) from None\n  File \"C:\\Users\\ANDRSD~1\\AppData\\Local\\Temp\\__autograph_generated_filethx4_r06.py\", line 15, in tf__train_function\n    retval_ = ag__.converted_call(ag__.ld(step_function), (ag__.ld(self), ag__.ld(iterator)), None, fscope)\nValueError: in user code:\n\n    File \"c:\\Users\\AndrÃ¨s DLR\\AppData\\Local\\Programs\\Python\\Python310\\lib\\site-packages\\keras\\src\\engine\\training.py\", line 1338, in train_function  *\n        return step_function(self, iterator)\n    File \"c:\\Users\\AndrÃ¨s DLR\\AppData\\Local\\Programs\\Python\\Python310\\lib\\site-packages\\keras\\src\\engine\\training.py\", line 1322, in step_function  **\n        outputs = model.distribute_strategy.run(run_step, args=(data,))\n    File \"c:\\Users\\AndrÃ¨s DLR\\AppData\\Local\\Programs\\Python\\Python310\\lib\\site-packages\\keras\\src\\engine\\training.py\", line 1303, in run_step  **\n        outputs = model.train_step(data)\n    File \"c:\\Users\\AndrÃ¨s DLR\\AppData\\Local\\Programs\\Python\\Python310\\lib\\site-packages\\keras\\src\\engine\\training.py\", line 1080, in train_step\n        y_pred = self(x, training=True)\n    File \"c:\\Users\\AndrÃ¨s DLR\\AppData\\Local\\Programs\\Python\\Python310\\lib\\site-packages\\keras\\src\\utils\\traceback_utils.py\", line 70, in error_handler\n        raise e.with_traceback(filtered_tb) from None\n    File \"c:\\Users\\AndrÃ¨s DLR\\AppData\\Local\\Programs\\Python\\Python310\\lib\\site-packages\\keras\\src\\engine\\input_spec.py\", line 298, in assert_input_compatibility\n        raise ValueError(\n\n    ValueError: Input 0 of layer \"sequential_89\" is incompatible with the layer: expected shape=(None, 8), found shape=(10, 5)\n\n\n--------------------------------------------------------------------------------\n1 fits failed with the following error:\nTraceback (most recent call last):\n  File \"c:\\Users\\AndrÃ¨s DLR\\AppData\\Local\\Programs\\Python\\Python310\\lib\\site-packages\\sklearn\\model_selection\\_validation.py\", line 686, in _fit_and_score\n    estimator.fit(X_train, y_train, **fit_params)\n  File \"c:\\Users\\AndrÃ¨s DLR\\AppData\\Local\\Programs\\Python\\Python310\\lib\\site-packages\\scikeras\\wrappers.py\", line 1491, in fit\n    super().fit(X=X, y=y, sample_weight=sample_weight, **kwargs)\n  File \"c:\\Users\\AndrÃ¨s DLR\\AppData\\Local\\Programs\\Python\\Python310\\lib\\site-packages\\scikeras\\wrappers.py\", line 760, in fit\n    self._fit(\n  File \"c:\\Users\\AndrÃ¨s DLR\\AppData\\Local\\Programs\\Python\\Python310\\lib\\site-packages\\scikeras\\wrappers.py\", line 928, in _fit\n    self._fit_keras_model(\n  File \"c:\\Users\\AndrÃ¨s DLR\\AppData\\Local\\Programs\\Python\\Python310\\lib\\site-packages\\scikeras\\wrappers.py\", line 524, in _fit_keras_model\n    hist = self.model_.fit(x=X, y=y, **fit_args)\n  File \"c:\\Users\\AndrÃ¨s DLR\\AppData\\Local\\Programs\\Python\\Python310\\lib\\site-packages\\keras\\src\\utils\\traceback_utils.py\", line 70, in error_handler\n    raise e.with_traceback(filtered_tb) from None\n  File \"C:\\Users\\ANDRSD~1\\AppData\\Local\\Temp\\__autograph_generated_filethx4_r06.py\", line 15, in tf__train_function\n    retval_ = ag__.converted_call(ag__.ld(step_function), (ag__.ld(self), ag__.ld(iterator)), None, fscope)\nValueError: in user code:\n\n    File \"c:\\Users\\AndrÃ¨s DLR\\AppData\\Local\\Programs\\Python\\Python310\\lib\\site-packages\\keras\\src\\engine\\training.py\", line 1338, in train_function  *\n        return step_function(self, iterator)\n    File \"c:\\Users\\AndrÃ¨s DLR\\AppData\\Local\\Programs\\Python\\Python310\\lib\\site-packages\\keras\\src\\engine\\training.py\", line 1322, in step_function  **\n        outputs = model.distribute_strategy.run(run_step, args=(data,))\n    File \"c:\\Users\\AndrÃ¨s DLR\\AppData\\Local\\Programs\\Python\\Python310\\lib\\site-packages\\keras\\src\\engine\\training.py\", line 1303, in run_step  **\n        outputs = model.train_step(data)\n    File \"c:\\Users\\AndrÃ¨s DLR\\AppData\\Local\\Programs\\Python\\Python310\\lib\\site-packages\\keras\\src\\engine\\training.py\", line 1080, in train_step\n        y_pred = self(x, training=True)\n    File \"c:\\Users\\AndrÃ¨s DLR\\AppData\\Local\\Programs\\Python\\Python310\\lib\\site-packages\\keras\\src\\utils\\traceback_utils.py\", line 70, in error_handler\n        raise e.with_traceback(filtered_tb) from None\n    File \"c:\\Users\\AndrÃ¨s DLR\\AppData\\Local\\Programs\\Python\\Python310\\lib\\site-packages\\keras\\src\\engine\\input_spec.py\", line 298, in assert_input_compatibility\n        raise ValueError(\n\n    ValueError: Input 0 of layer \"sequential_90\" is incompatible with the layer: expected shape=(None, 8), found shape=(10, 5)\n\n\n--------------------------------------------------------------------------------\n1 fits failed with the following error:\nTraceback (most recent call last):\n  File \"c:\\Users\\AndrÃ¨s DLR\\AppData\\Local\\Programs\\Python\\Python310\\lib\\site-packages\\sklearn\\model_selection\\_validation.py\", line 686, in _fit_and_score\n    estimator.fit(X_train, y_train, **fit_params)\n  File \"c:\\Users\\AndrÃ¨s DLR\\AppData\\Local\\Programs\\Python\\Python310\\lib\\site-packages\\scikeras\\wrappers.py\", line 1491, in fit\n    super().fit(X=X, y=y, sample_weight=sample_weight, **kwargs)\n  File \"c:\\Users\\AndrÃ¨s DLR\\AppData\\Local\\Programs\\Python\\Python310\\lib\\site-packages\\scikeras\\wrappers.py\", line 760, in fit\n    self._fit(\n  File \"c:\\Users\\AndrÃ¨s DLR\\AppData\\Local\\Programs\\Python\\Python310\\lib\\site-packages\\scikeras\\wrappers.py\", line 928, in _fit\n    self._fit_keras_model(\n  File \"c:\\Users\\AndrÃ¨s DLR\\AppData\\Local\\Programs\\Python\\Python310\\lib\\site-packages\\scikeras\\wrappers.py\", line 524, in _fit_keras_model\n    hist = self.model_.fit(x=X, y=y, **fit_args)\n  File \"c:\\Users\\AndrÃ¨s DLR\\AppData\\Local\\Programs\\Python\\Python310\\lib\\site-packages\\keras\\src\\utils\\traceback_utils.py\", line 70, in error_handler\n    raise e.with_traceback(filtered_tb) from None\n  File \"C:\\Users\\ANDRSD~1\\AppData\\Local\\Temp\\__autograph_generated_filethx4_r06.py\", line 15, in tf__train_function\n    retval_ = ag__.converted_call(ag__.ld(step_function), (ag__.ld(self), ag__.ld(iterator)), None, fscope)\nValueError: in user code:\n\n    File \"c:\\Users\\AndrÃ¨s DLR\\AppData\\Local\\Programs\\Python\\Python310\\lib\\site-packages\\keras\\src\\engine\\training.py\", line 1338, in train_function  *\n        return step_function(self, iterator)\n    File \"c:\\Users\\AndrÃ¨s DLR\\AppData\\Local\\Programs\\Python\\Python310\\lib\\site-packages\\keras\\src\\engine\\training.py\", line 1322, in step_function  **\n        outputs = model.distribute_strategy.run(run_step, args=(data,))\n    File \"c:\\Users\\AndrÃ¨s DLR\\AppData\\Local\\Programs\\Python\\Python310\\lib\\site-packages\\keras\\src\\engine\\training.py\", line 1303, in run_step  **\n        outputs = model.train_step(data)\n    File \"c:\\Users\\AndrÃ¨s DLR\\AppData\\Local\\Programs\\Python\\Python310\\lib\\site-packages\\keras\\src\\engine\\training.py\", line 1080, in train_step\n        y_pred = self(x, training=True)\n    File \"c:\\Users\\AndrÃ¨s DLR\\AppData\\Local\\Programs\\Python\\Python310\\lib\\site-packages\\keras\\src\\utils\\traceback_utils.py\", line 70, in error_handler\n        raise e.with_traceback(filtered_tb) from None\n    File \"c:\\Users\\AndrÃ¨s DLR\\AppData\\Local\\Programs\\Python\\Python310\\lib\\site-packages\\keras\\src\\engine\\input_spec.py\", line 298, in assert_input_compatibility\n        raise ValueError(\n\n    ValueError: Input 0 of layer \"sequential_91\" is incompatible with the layer: expected shape=(None, 8), found shape=(10, 5)\n\n\n--------------------------------------------------------------------------------\n1 fits failed with the following error:\nTraceback (most recent call last):\n  File \"c:\\Users\\AndrÃ¨s DLR\\AppData\\Local\\Programs\\Python\\Python310\\lib\\site-packages\\sklearn\\model_selection\\_validation.py\", line 686, in _fit_and_score\n    estimator.fit(X_train, y_train, **fit_params)\n  File \"c:\\Users\\AndrÃ¨s DLR\\AppData\\Local\\Programs\\Python\\Python310\\lib\\site-packages\\scikeras\\wrappers.py\", line 1491, in fit\n    super().fit(X=X, y=y, sample_weight=sample_weight, **kwargs)\n  File \"c:\\Users\\AndrÃ¨s DLR\\AppData\\Local\\Programs\\Python\\Python310\\lib\\site-packages\\scikeras\\wrappers.py\", line 760, in fit\n    self._fit(\n  File \"c:\\Users\\AndrÃ¨s DLR\\AppData\\Local\\Programs\\Python\\Python310\\lib\\site-packages\\scikeras\\wrappers.py\", line 928, in _fit\n    self._fit_keras_model(\n  File \"c:\\Users\\AndrÃ¨s DLR\\AppData\\Local\\Programs\\Python\\Python310\\lib\\site-packages\\scikeras\\wrappers.py\", line 524, in _fit_keras_model\n    hist = self.model_.fit(x=X, y=y, **fit_args)\n  File \"c:\\Users\\AndrÃ¨s DLR\\AppData\\Local\\Programs\\Python\\Python310\\lib\\site-packages\\keras\\src\\utils\\traceback_utils.py\", line 70, in error_handler\n    raise e.with_traceback(filtered_tb) from None\n  File \"C:\\Users\\ANDRSD~1\\AppData\\Local\\Temp\\__autograph_generated_filethx4_r06.py\", line 15, in tf__train_function\n    retval_ = ag__.converted_call(ag__.ld(step_function), (ag__.ld(self), ag__.ld(iterator)), None, fscope)\nValueError: in user code:\n\n    File \"c:\\Users\\AndrÃ¨s DLR\\AppData\\Local\\Programs\\Python\\Python310\\lib\\site-packages\\keras\\src\\engine\\training.py\", line 1338, in train_function  *\n        return step_function(self, iterator)\n    File \"c:\\Users\\AndrÃ¨s DLR\\AppData\\Local\\Programs\\Python\\Python310\\lib\\site-packages\\keras\\src\\engine\\training.py\", line 1322, in step_function  **\n        outputs = model.distribute_strategy.run(run_step, args=(data,))\n    File \"c:\\Users\\AndrÃ¨s DLR\\AppData\\Local\\Programs\\Python\\Python310\\lib\\site-packages\\keras\\src\\engine\\training.py\", line 1303, in run_step  **\n        outputs = model.train_step(data)\n    File \"c:\\Users\\AndrÃ¨s DLR\\AppData\\Local\\Programs\\Python\\Python310\\lib\\site-packages\\keras\\src\\engine\\training.py\", line 1080, in train_step\n        y_pred = self(x, training=True)\n    File \"c:\\Users\\AndrÃ¨s DLR\\AppData\\Local\\Programs\\Python\\Python310\\lib\\site-packages\\keras\\src\\utils\\traceback_utils.py\", line 70, in error_handler\n        raise e.with_traceback(filtered_tb) from None\n    File \"c:\\Users\\AndrÃ¨s DLR\\AppData\\Local\\Programs\\Python\\Python310\\lib\\site-packages\\keras\\src\\engine\\input_spec.py\", line 298, in assert_input_compatibility\n        raise ValueError(\n\n    ValueError: Input 0 of layer \"sequential_92\" is incompatible with the layer: expected shape=(None, 8), found shape=(10, 5)\n\n\n--------------------------------------------------------------------------------\n1 fits failed with the following error:\nTraceback (most recent call last):\n  File \"c:\\Users\\AndrÃ¨s DLR\\AppData\\Local\\Programs\\Python\\Python310\\lib\\site-packages\\sklearn\\model_selection\\_validation.py\", line 686, in _fit_and_score\n    estimator.fit(X_train, y_train, **fit_params)\n  File \"c:\\Users\\AndrÃ¨s DLR\\AppData\\Local\\Programs\\Python\\Python310\\lib\\site-packages\\scikeras\\wrappers.py\", line 1491, in fit\n    super().fit(X=X, y=y, sample_weight=sample_weight, **kwargs)\n  File \"c:\\Users\\AndrÃ¨s DLR\\AppData\\Local\\Programs\\Python\\Python310\\lib\\site-packages\\scikeras\\wrappers.py\", line 760, in fit\n    self._fit(\n  File \"c:\\Users\\AndrÃ¨s DLR\\AppData\\Local\\Programs\\Python\\Python310\\lib\\site-packages\\scikeras\\wrappers.py\", line 928, in _fit\n    self._fit_keras_model(\n  File \"c:\\Users\\AndrÃ¨s DLR\\AppData\\Local\\Programs\\Python\\Python310\\lib\\site-packages\\scikeras\\wrappers.py\", line 524, in _fit_keras_model\n    hist = self.model_.fit(x=X, y=y, **fit_args)\n  File \"c:\\Users\\AndrÃ¨s DLR\\AppData\\Local\\Programs\\Python\\Python310\\lib\\site-packages\\keras\\src\\utils\\traceback_utils.py\", line 70, in error_handler\n    raise e.with_traceback(filtered_tb) from None\n  File \"C:\\Users\\ANDRSD~1\\AppData\\Local\\Temp\\__autograph_generated_filethx4_r06.py\", line 15, in tf__train_function\n    retval_ = ag__.converted_call(ag__.ld(step_function), (ag__.ld(self), ag__.ld(iterator)), None, fscope)\nValueError: in user code:\n\n    File \"c:\\Users\\AndrÃ¨s DLR\\AppData\\Local\\Programs\\Python\\Python310\\lib\\site-packages\\keras\\src\\engine\\training.py\", line 1338, in train_function  *\n        return step_function(self, iterator)\n    File \"c:\\Users\\AndrÃ¨s DLR\\AppData\\Local\\Programs\\Python\\Python310\\lib\\site-packages\\keras\\src\\engine\\training.py\", line 1322, in step_function  **\n        outputs = model.distribute_strategy.run(run_step, args=(data,))\n    File \"c:\\Users\\AndrÃ¨s DLR\\AppData\\Local\\Programs\\Python\\Python310\\lib\\site-packages\\keras\\src\\engine\\training.py\", line 1303, in run_step  **\n        outputs = model.train_step(data)\n    File \"c:\\Users\\AndrÃ¨s DLR\\AppData\\Local\\Programs\\Python\\Python310\\lib\\site-packages\\keras\\src\\engine\\training.py\", line 1080, in train_step\n        y_pred = self(x, training=True)\n    File \"c:\\Users\\AndrÃ¨s DLR\\AppData\\Local\\Programs\\Python\\Python310\\lib\\site-packages\\keras\\src\\utils\\traceback_utils.py\", line 70, in error_handler\n        raise e.with_traceback(filtered_tb) from None\n    File \"c:\\Users\\AndrÃ¨s DLR\\AppData\\Local\\Programs\\Python\\Python310\\lib\\site-packages\\keras\\src\\engine\\input_spec.py\", line 298, in assert_input_compatibility\n        raise ValueError(\n\n    ValueError: Input 0 of layer \"sequential_93\" is incompatible with the layer: expected shape=(None, 8), found shape=(10, 5)\n\n\n--------------------------------------------------------------------------------\n1 fits failed with the following error:\nTraceback (most recent call last):\n  File \"c:\\Users\\AndrÃ¨s DLR\\AppData\\Local\\Programs\\Python\\Python310\\lib\\site-packages\\sklearn\\model_selection\\_validation.py\", line 686, in _fit_and_score\n    estimator.fit(X_train, y_train, **fit_params)\n  File \"c:\\Users\\AndrÃ¨s DLR\\AppData\\Local\\Programs\\Python\\Python310\\lib\\site-packages\\scikeras\\wrappers.py\", line 1491, in fit\n    super().fit(X=X, y=y, sample_weight=sample_weight, **kwargs)\n  File \"c:\\Users\\AndrÃ¨s DLR\\AppData\\Local\\Programs\\Python\\Python310\\lib\\site-packages\\scikeras\\wrappers.py\", line 760, in fit\n    self._fit(\n  File \"c:\\Users\\AndrÃ¨s DLR\\AppData\\Local\\Programs\\Python\\Python310\\lib\\site-packages\\scikeras\\wrappers.py\", line 928, in _fit\n    self._fit_keras_model(\n  File \"c:\\Users\\AndrÃ¨s DLR\\AppData\\Local\\Programs\\Python\\Python310\\lib\\site-packages\\scikeras\\wrappers.py\", line 524, in _fit_keras_model\n    hist = self.model_.fit(x=X, y=y, **fit_args)\n  File \"c:\\Users\\AndrÃ¨s DLR\\AppData\\Local\\Programs\\Python\\Python310\\lib\\site-packages\\keras\\src\\utils\\traceback_utils.py\", line 70, in error_handler\n    raise e.with_traceback(filtered_tb) from None\n  File \"C:\\Users\\ANDRSD~1\\AppData\\Local\\Temp\\__autograph_generated_filethx4_r06.py\", line 15, in tf__train_function\n    retval_ = ag__.converted_call(ag__.ld(step_function), (ag__.ld(self), ag__.ld(iterator)), None, fscope)\nValueError: in user code:\n\n    File \"c:\\Users\\AndrÃ¨s DLR\\AppData\\Local\\Programs\\Python\\Python310\\lib\\site-packages\\keras\\src\\engine\\training.py\", line 1338, in train_function  *\n        return step_function(self, iterator)\n    File \"c:\\Users\\AndrÃ¨s DLR\\AppData\\Local\\Programs\\Python\\Python310\\lib\\site-packages\\keras\\src\\engine\\training.py\", line 1322, in step_function  **\n        outputs = model.distribute_strategy.run(run_step, args=(data,))\n    File \"c:\\Users\\AndrÃ¨s DLR\\AppData\\Local\\Programs\\Python\\Python310\\lib\\site-packages\\keras\\src\\engine\\training.py\", line 1303, in run_step  **\n        outputs = model.train_step(data)\n    File \"c:\\Users\\AndrÃ¨s DLR\\AppData\\Local\\Programs\\Python\\Python310\\lib\\site-packages\\keras\\src\\engine\\training.py\", line 1080, in train_step\n        y_pred = self(x, training=True)\n    File \"c:\\Users\\AndrÃ¨s DLR\\AppData\\Local\\Programs\\Python\\Python310\\lib\\site-packages\\keras\\src\\utils\\traceback_utils.py\", line 70, in error_handler\n        raise e.with_traceback(filtered_tb) from None\n    File \"c:\\Users\\AndrÃ¨s DLR\\AppData\\Local\\Programs\\Python\\Python310\\lib\\site-packages\\keras\\src\\engine\\input_spec.py\", line 298, in assert_input_compatibility\n        raise ValueError(\n\n    ValueError: Input 0 of layer \"sequential_94\" is incompatible with the layer: expected shape=(None, 8), found shape=(10, 5)\n\n\n--------------------------------------------------------------------------------\n1 fits failed with the following error:\nTraceback (most recent call last):\n  File \"c:\\Users\\AndrÃ¨s DLR\\AppData\\Local\\Programs\\Python\\Python310\\lib\\site-packages\\sklearn\\model_selection\\_validation.py\", line 686, in _fit_and_score\n    estimator.fit(X_train, y_train, **fit_params)\n  File \"c:\\Users\\AndrÃ¨s DLR\\AppData\\Local\\Programs\\Python\\Python310\\lib\\site-packages\\scikeras\\wrappers.py\", line 1491, in fit\n    super().fit(X=X, y=y, sample_weight=sample_weight, **kwargs)\n  File \"c:\\Users\\AndrÃ¨s DLR\\AppData\\Local\\Programs\\Python\\Python310\\lib\\site-packages\\scikeras\\wrappers.py\", line 760, in fit\n    self._fit(\n  File \"c:\\Users\\AndrÃ¨s DLR\\AppData\\Local\\Programs\\Python\\Python310\\lib\\site-packages\\scikeras\\wrappers.py\", line 928, in _fit\n    self._fit_keras_model(\n  File \"c:\\Users\\AndrÃ¨s DLR\\AppData\\Local\\Programs\\Python\\Python310\\lib\\site-packages\\scikeras\\wrappers.py\", line 524, in _fit_keras_model\n    hist = self.model_.fit(x=X, y=y, **fit_args)\n  File \"c:\\Users\\AndrÃ¨s DLR\\AppData\\Local\\Programs\\Python\\Python310\\lib\\site-packages\\keras\\src\\utils\\traceback_utils.py\", line 70, in error_handler\n    raise e.with_traceback(filtered_tb) from None\n  File \"C:\\Users\\ANDRSD~1\\AppData\\Local\\Temp\\__autograph_generated_filethx4_r06.py\", line 15, in tf__train_function\n    retval_ = ag__.converted_call(ag__.ld(step_function), (ag__.ld(self), ag__.ld(iterator)), None, fscope)\nValueError: in user code:\n\n    File \"c:\\Users\\AndrÃ¨s DLR\\AppData\\Local\\Programs\\Python\\Python310\\lib\\site-packages\\keras\\src\\engine\\training.py\", line 1338, in train_function  *\n        return step_function(self, iterator)\n    File \"c:\\Users\\AndrÃ¨s DLR\\AppData\\Local\\Programs\\Python\\Python310\\lib\\site-packages\\keras\\src\\engine\\training.py\", line 1322, in step_function  **\n        outputs = model.distribute_strategy.run(run_step, args=(data,))\n    File \"c:\\Users\\AndrÃ¨s DLR\\AppData\\Local\\Programs\\Python\\Python310\\lib\\site-packages\\keras\\src\\engine\\training.py\", line 1303, in run_step  **\n        outputs = model.train_step(data)\n    File \"c:\\Users\\AndrÃ¨s DLR\\AppData\\Local\\Programs\\Python\\Python310\\lib\\site-packages\\keras\\src\\engine\\training.py\", line 1080, in train_step\n        y_pred = self(x, training=True)\n    File \"c:\\Users\\AndrÃ¨s DLR\\AppData\\Local\\Programs\\Python\\Python310\\lib\\site-packages\\keras\\src\\utils\\traceback_utils.py\", line 70, in error_handler\n        raise e.with_traceback(filtered_tb) from None\n    File \"c:\\Users\\AndrÃ¨s DLR\\AppData\\Local\\Programs\\Python\\Python310\\lib\\site-packages\\keras\\src\\engine\\input_spec.py\", line 298, in assert_input_compatibility\n        raise ValueError(\n\n    ValueError: Input 0 of layer \"sequential_95\" is incompatible with the layer: expected shape=(None, 8), found shape=(10, 5)\n\n\n--------------------------------------------------------------------------------\n1 fits failed with the following error:\nTraceback (most recent call last):\n  File \"c:\\Users\\AndrÃ¨s DLR\\AppData\\Local\\Programs\\Python\\Python310\\lib\\site-packages\\sklearn\\model_selection\\_validation.py\", line 686, in _fit_and_score\n    estimator.fit(X_train, y_train, **fit_params)\n  File \"c:\\Users\\AndrÃ¨s DLR\\AppData\\Local\\Programs\\Python\\Python310\\lib\\site-packages\\scikeras\\wrappers.py\", line 1491, in fit\n    super().fit(X=X, y=y, sample_weight=sample_weight, **kwargs)\n  File \"c:\\Users\\AndrÃ¨s DLR\\AppData\\Local\\Programs\\Python\\Python310\\lib\\site-packages\\scikeras\\wrappers.py\", line 760, in fit\n    self._fit(\n  File \"c:\\Users\\AndrÃ¨s DLR\\AppData\\Local\\Programs\\Python\\Python310\\lib\\site-packages\\scikeras\\wrappers.py\", line 928, in _fit\n    self._fit_keras_model(\n  File \"c:\\Users\\AndrÃ¨s DLR\\AppData\\Local\\Programs\\Python\\Python310\\lib\\site-packages\\scikeras\\wrappers.py\", line 524, in _fit_keras_model\n    hist = self.model_.fit(x=X, y=y, **fit_args)\n  File \"c:\\Users\\AndrÃ¨s DLR\\AppData\\Local\\Programs\\Python\\Python310\\lib\\site-packages\\keras\\src\\utils\\traceback_utils.py\", line 70, in error_handler\n    raise e.with_traceback(filtered_tb) from None\n  File \"C:\\Users\\ANDRSD~1\\AppData\\Local\\Temp\\__autograph_generated_filethx4_r06.py\", line 15, in tf__train_function\n    retval_ = ag__.converted_call(ag__.ld(step_function), (ag__.ld(self), ag__.ld(iterator)), None, fscope)\nValueError: in user code:\n\n    File \"c:\\Users\\AndrÃ¨s DLR\\AppData\\Local\\Programs\\Python\\Python310\\lib\\site-packages\\keras\\src\\engine\\training.py\", line 1338, in train_function  *\n        return step_function(self, iterator)\n    File \"c:\\Users\\AndrÃ¨s DLR\\AppData\\Local\\Programs\\Python\\Python310\\lib\\site-packages\\keras\\src\\engine\\training.py\", line 1322, in step_function  **\n        outputs = model.distribute_strategy.run(run_step, args=(data,))\n    File \"c:\\Users\\AndrÃ¨s DLR\\AppData\\Local\\Programs\\Python\\Python310\\lib\\site-packages\\keras\\src\\engine\\training.py\", line 1303, in run_step  **\n        outputs = model.train_step(data)\n    File \"c:\\Users\\AndrÃ¨s DLR\\AppData\\Local\\Programs\\Python\\Python310\\lib\\site-packages\\keras\\src\\engine\\training.py\", line 1080, in train_step\n        y_pred = self(x, training=True)\n    File \"c:\\Users\\AndrÃ¨s DLR\\AppData\\Local\\Programs\\Python\\Python310\\lib\\site-packages\\keras\\src\\utils\\traceback_utils.py\", line 70, in error_handler\n        raise e.with_traceback(filtered_tb) from None\n    File \"c:\\Users\\AndrÃ¨s DLR\\AppData\\Local\\Programs\\Python\\Python310\\lib\\site-packages\\keras\\src\\engine\\input_spec.py\", line 298, in assert_input_compatibility\n        raise ValueError(\n\n    ValueError: Input 0 of layer \"sequential_96\" is incompatible with the layer: expected shape=(None, 8), found shape=(10, 5)\n\n\n--------------------------------------------------------------------------------\n1 fits failed with the following error:\nTraceback (most recent call last):\n  File \"c:\\Users\\AndrÃ¨s DLR\\AppData\\Local\\Programs\\Python\\Python310\\lib\\site-packages\\sklearn\\model_selection\\_validation.py\", line 686, in _fit_and_score\n    estimator.fit(X_train, y_train, **fit_params)\n  File \"c:\\Users\\AndrÃ¨s DLR\\AppData\\Local\\Programs\\Python\\Python310\\lib\\site-packages\\scikeras\\wrappers.py\", line 1491, in fit\n    super().fit(X=X, y=y, sample_weight=sample_weight, **kwargs)\n  File \"c:\\Users\\AndrÃ¨s DLR\\AppData\\Local\\Programs\\Python\\Python310\\lib\\site-packages\\scikeras\\wrappers.py\", line 760, in fit\n    self._fit(\n  File \"c:\\Users\\AndrÃ¨s DLR\\AppData\\Local\\Programs\\Python\\Python310\\lib\\site-packages\\scikeras\\wrappers.py\", line 928, in _fit\n    self._fit_keras_model(\n  File \"c:\\Users\\AndrÃ¨s DLR\\AppData\\Local\\Programs\\Python\\Python310\\lib\\site-packages\\scikeras\\wrappers.py\", line 524, in _fit_keras_model\n    hist = self.model_.fit(x=X, y=y, **fit_args)\n  File \"c:\\Users\\AndrÃ¨s DLR\\AppData\\Local\\Programs\\Python\\Python310\\lib\\site-packages\\keras\\src\\utils\\traceback_utils.py\", line 70, in error_handler\n    raise e.with_traceback(filtered_tb) from None\n  File \"C:\\Users\\ANDRSD~1\\AppData\\Local\\Temp\\__autograph_generated_filethx4_r06.py\", line 15, in tf__train_function\n    retval_ = ag__.converted_call(ag__.ld(step_function), (ag__.ld(self), ag__.ld(iterator)), None, fscope)\nValueError: in user code:\n\n    File \"c:\\Users\\AndrÃ¨s DLR\\AppData\\Local\\Programs\\Python\\Python310\\lib\\site-packages\\keras\\src\\engine\\training.py\", line 1338, in train_function  *\n        return step_function(self, iterator)\n    File \"c:\\Users\\AndrÃ¨s DLR\\AppData\\Local\\Programs\\Python\\Python310\\lib\\site-packages\\keras\\src\\engine\\training.py\", line 1322, in step_function  **\n        outputs = model.distribute_strategy.run(run_step, args=(data,))\n    File \"c:\\Users\\AndrÃ¨s DLR\\AppData\\Local\\Programs\\Python\\Python310\\lib\\site-packages\\keras\\src\\engine\\training.py\", line 1303, in run_step  **\n        outputs = model.train_step(data)\n    File \"c:\\Users\\AndrÃ¨s DLR\\AppData\\Local\\Programs\\Python\\Python310\\lib\\site-packages\\keras\\src\\engine\\training.py\", line 1080, in train_step\n        y_pred = self(x, training=True)\n    File \"c:\\Users\\AndrÃ¨s DLR\\AppData\\Local\\Programs\\Python\\Python310\\lib\\site-packages\\keras\\src\\utils\\traceback_utils.py\", line 70, in error_handler\n        raise e.with_traceback(filtered_tb) from None\n    File \"c:\\Users\\AndrÃ¨s DLR\\AppData\\Local\\Programs\\Python\\Python310\\lib\\site-packages\\keras\\src\\engine\\input_spec.py\", line 298, in assert_input_compatibility\n        raise ValueError(\n\n    ValueError: Input 0 of layer \"sequential_97\" is incompatible with the layer: expected shape=(None, 8), found shape=(10, 5)\n\n\n--------------------------------------------------------------------------------\n1 fits failed with the following error:\nTraceback (most recent call last):\n  File \"c:\\Users\\AndrÃ¨s DLR\\AppData\\Local\\Programs\\Python\\Python310\\lib\\site-packages\\sklearn\\model_selection\\_validation.py\", line 686, in _fit_and_score\n    estimator.fit(X_train, y_train, **fit_params)\n  File \"c:\\Users\\AndrÃ¨s DLR\\AppData\\Local\\Programs\\Python\\Python310\\lib\\site-packages\\scikeras\\wrappers.py\", line 1491, in fit\n    super().fit(X=X, y=y, sample_weight=sample_weight, **kwargs)\n  File \"c:\\Users\\AndrÃ¨s DLR\\AppData\\Local\\Programs\\Python\\Python310\\lib\\site-packages\\scikeras\\wrappers.py\", line 760, in fit\n    self._fit(\n  File \"c:\\Users\\AndrÃ¨s DLR\\AppData\\Local\\Programs\\Python\\Python310\\lib\\site-packages\\scikeras\\wrappers.py\", line 928, in _fit\n    self._fit_keras_model(\n  File \"c:\\Users\\AndrÃ¨s DLR\\AppData\\Local\\Programs\\Python\\Python310\\lib\\site-packages\\scikeras\\wrappers.py\", line 524, in _fit_keras_model\n    hist = self.model_.fit(x=X, y=y, **fit_args)\n  File \"c:\\Users\\AndrÃ¨s DLR\\AppData\\Local\\Programs\\Python\\Python310\\lib\\site-packages\\keras\\src\\utils\\traceback_utils.py\", line 70, in error_handler\n    raise e.with_traceback(filtered_tb) from None\n  File \"C:\\Users\\ANDRSD~1\\AppData\\Local\\Temp\\__autograph_generated_filethx4_r06.py\", line 15, in tf__train_function\n    retval_ = ag__.converted_call(ag__.ld(step_function), (ag__.ld(self), ag__.ld(iterator)), None, fscope)\nValueError: in user code:\n\n    File \"c:\\Users\\AndrÃ¨s DLR\\AppData\\Local\\Programs\\Python\\Python310\\lib\\site-packages\\keras\\src\\engine\\training.py\", line 1338, in train_function  *\n        return step_function(self, iterator)\n    File \"c:\\Users\\AndrÃ¨s DLR\\AppData\\Local\\Programs\\Python\\Python310\\lib\\site-packages\\keras\\src\\engine\\training.py\", line 1322, in step_function  **\n        outputs = model.distribute_strategy.run(run_step, args=(data,))\n    File \"c:\\Users\\AndrÃ¨s DLR\\AppData\\Local\\Programs\\Python\\Python310\\lib\\site-packages\\keras\\src\\engine\\training.py\", line 1303, in run_step  **\n        outputs = model.train_step(data)\n    File \"c:\\Users\\AndrÃ¨s DLR\\AppData\\Local\\Programs\\Python\\Python310\\lib\\site-packages\\keras\\src\\engine\\training.py\", line 1080, in train_step\n        y_pred = self(x, training=True)\n    File \"c:\\Users\\AndrÃ¨s DLR\\AppData\\Local\\Programs\\Python\\Python310\\lib\\site-packages\\keras\\src\\utils\\traceback_utils.py\", line 70, in error_handler\n        raise e.with_traceback(filtered_tb) from None\n    File \"c:\\Users\\AndrÃ¨s DLR\\AppData\\Local\\Programs\\Python\\Python310\\lib\\site-packages\\keras\\src\\engine\\input_spec.py\", line 298, in assert_input_compatibility\n        raise ValueError(\n\n    ValueError: Input 0 of layer \"sequential_98\" is incompatible with the layer: expected shape=(None, 8), found shape=(10, 5)\n\n\n--------------------------------------------------------------------------------\n1 fits failed with the following error:\nTraceback (most recent call last):\n  File \"c:\\Users\\AndrÃ¨s DLR\\AppData\\Local\\Programs\\Python\\Python310\\lib\\site-packages\\sklearn\\model_selection\\_validation.py\", line 686, in _fit_and_score\n    estimator.fit(X_train, y_train, **fit_params)\n  File \"c:\\Users\\AndrÃ¨s DLR\\AppData\\Local\\Programs\\Python\\Python310\\lib\\site-packages\\scikeras\\wrappers.py\", line 1491, in fit\n    super().fit(X=X, y=y, sample_weight=sample_weight, **kwargs)\n  File \"c:\\Users\\AndrÃ¨s DLR\\AppData\\Local\\Programs\\Python\\Python310\\lib\\site-packages\\scikeras\\wrappers.py\", line 760, in fit\n    self._fit(\n  File \"c:\\Users\\AndrÃ¨s DLR\\AppData\\Local\\Programs\\Python\\Python310\\lib\\site-packages\\scikeras\\wrappers.py\", line 928, in _fit\n    self._fit_keras_model(\n  File \"c:\\Users\\AndrÃ¨s DLR\\AppData\\Local\\Programs\\Python\\Python310\\lib\\site-packages\\scikeras\\wrappers.py\", line 524, in _fit_keras_model\n    hist = self.model_.fit(x=X, y=y, **fit_args)\n  File \"c:\\Users\\AndrÃ¨s DLR\\AppData\\Local\\Programs\\Python\\Python310\\lib\\site-packages\\keras\\src\\utils\\traceback_utils.py\", line 70, in error_handler\n    raise e.with_traceback(filtered_tb) from None\n  File \"C:\\Users\\ANDRSD~1\\AppData\\Local\\Temp\\__autograph_generated_filethx4_r06.py\", line 15, in tf__train_function\n    retval_ = ag__.converted_call(ag__.ld(step_function), (ag__.ld(self), ag__.ld(iterator)), None, fscope)\nValueError: in user code:\n\n    File \"c:\\Users\\AndrÃ¨s DLR\\AppData\\Local\\Programs\\Python\\Python310\\lib\\site-packages\\keras\\src\\engine\\training.py\", line 1338, in train_function  *\n        return step_function(self, iterator)\n    File \"c:\\Users\\AndrÃ¨s DLR\\AppData\\Local\\Programs\\Python\\Python310\\lib\\site-packages\\keras\\src\\engine\\training.py\", line 1322, in step_function  **\n        outputs = model.distribute_strategy.run(run_step, args=(data,))\n    File \"c:\\Users\\AndrÃ¨s DLR\\AppData\\Local\\Programs\\Python\\Python310\\lib\\site-packages\\keras\\src\\engine\\training.py\", line 1303, in run_step  **\n        outputs = model.train_step(data)\n    File \"c:\\Users\\AndrÃ¨s DLR\\AppData\\Local\\Programs\\Python\\Python310\\lib\\site-packages\\keras\\src\\engine\\training.py\", line 1080, in train_step\n        y_pred = self(x, training=True)\n    File \"c:\\Users\\AndrÃ¨s DLR\\AppData\\Local\\Programs\\Python\\Python310\\lib\\site-packages\\keras\\src\\utils\\traceback_utils.py\", line 70, in error_handler\n        raise e.with_traceback(filtered_tb) from None\n    File \"c:\\Users\\AndrÃ¨s DLR\\AppData\\Local\\Programs\\Python\\Python310\\lib\\site-packages\\keras\\src\\engine\\input_spec.py\", line 298, in assert_input_compatibility\n        raise ValueError(\n\n    ValueError: Input 0 of layer \"sequential_99\" is incompatible with the layer: expected shape=(None, 8), found shape=(10, 5)\n\n\n--------------------------------------------------------------------------------\n1 fits failed with the following error:\nTraceback (most recent call last):\n  File \"c:\\Users\\AndrÃ¨s DLR\\AppData\\Local\\Programs\\Python\\Python310\\lib\\site-packages\\sklearn\\model_selection\\_validation.py\", line 686, in _fit_and_score\n    estimator.fit(X_train, y_train, **fit_params)\n  File \"c:\\Users\\AndrÃ¨s DLR\\AppData\\Local\\Programs\\Python\\Python310\\lib\\site-packages\\scikeras\\wrappers.py\", line 1491, in fit\n    super().fit(X=X, y=y, sample_weight=sample_weight, **kwargs)\n  File \"c:\\Users\\AndrÃ¨s DLR\\AppData\\Local\\Programs\\Python\\Python310\\lib\\site-packages\\scikeras\\wrappers.py\", line 760, in fit\n    self._fit(\n  File \"c:\\Users\\AndrÃ¨s DLR\\AppData\\Local\\Programs\\Python\\Python310\\lib\\site-packages\\scikeras\\wrappers.py\", line 928, in _fit\n    self._fit_keras_model(\n  File \"c:\\Users\\AndrÃ¨s DLR\\AppData\\Local\\Programs\\Python\\Python310\\lib\\site-packages\\scikeras\\wrappers.py\", line 524, in _fit_keras_model\n    hist = self.model_.fit(x=X, y=y, **fit_args)\n  File \"c:\\Users\\AndrÃ¨s DLR\\AppData\\Local\\Programs\\Python\\Python310\\lib\\site-packages\\keras\\src\\utils\\traceback_utils.py\", line 70, in error_handler\n    raise e.with_traceback(filtered_tb) from None\n  File \"C:\\Users\\ANDRSD~1\\AppData\\Local\\Temp\\__autograph_generated_filethx4_r06.py\", line 15, in tf__train_function\n    retval_ = ag__.converted_call(ag__.ld(step_function), (ag__.ld(self), ag__.ld(iterator)), None, fscope)\nValueError: in user code:\n\n    File \"c:\\Users\\AndrÃ¨s DLR\\AppData\\Local\\Programs\\Python\\Python310\\lib\\site-packages\\keras\\src\\engine\\training.py\", line 1338, in train_function  *\n        return step_function(self, iterator)\n    File \"c:\\Users\\AndrÃ¨s DLR\\AppData\\Local\\Programs\\Python\\Python310\\lib\\site-packages\\keras\\src\\engine\\training.py\", line 1322, in step_function  **\n        outputs = model.distribute_strategy.run(run_step, args=(data,))\n    File \"c:\\Users\\AndrÃ¨s DLR\\AppData\\Local\\Programs\\Python\\Python310\\lib\\site-packages\\keras\\src\\engine\\training.py\", line 1303, in run_step  **\n        outputs = model.train_step(data)\n    File \"c:\\Users\\AndrÃ¨s DLR\\AppData\\Local\\Programs\\Python\\Python310\\lib\\site-packages\\keras\\src\\engine\\training.py\", line 1080, in train_step\n        y_pred = self(x, training=True)\n    File \"c:\\Users\\AndrÃ¨s DLR\\AppData\\Local\\Programs\\Python\\Python310\\lib\\site-packages\\keras\\src\\utils\\traceback_utils.py\", line 70, in error_handler\n        raise e.with_traceback(filtered_tb) from None\n    File \"c:\\Users\\AndrÃ¨s DLR\\AppData\\Local\\Programs\\Python\\Python310\\lib\\site-packages\\keras\\src\\engine\\input_spec.py\", line 298, in assert_input_compatibility\n        raise ValueError(\n\n    ValueError: Input 0 of layer \"sequential_100\" is incompatible with the layer: expected shape=(None, 8), found shape=(10, 5)\n\n\n--------------------------------------------------------------------------------\n1 fits failed with the following error:\nTraceback (most recent call last):\n  File \"c:\\Users\\AndrÃ¨s DLR\\AppData\\Local\\Programs\\Python\\Python310\\lib\\site-packages\\sklearn\\model_selection\\_validation.py\", line 686, in _fit_and_score\n    estimator.fit(X_train, y_train, **fit_params)\n  File \"c:\\Users\\AndrÃ¨s DLR\\AppData\\Local\\Programs\\Python\\Python310\\lib\\site-packages\\scikeras\\wrappers.py\", line 1491, in fit\n    super().fit(X=X, y=y, sample_weight=sample_weight, **kwargs)\n  File \"c:\\Users\\AndrÃ¨s DLR\\AppData\\Local\\Programs\\Python\\Python310\\lib\\site-packages\\scikeras\\wrappers.py\", line 760, in fit\n    self._fit(\n  File \"c:\\Users\\AndrÃ¨s DLR\\AppData\\Local\\Programs\\Python\\Python310\\lib\\site-packages\\scikeras\\wrappers.py\", line 928, in _fit\n    self._fit_keras_model(\n  File \"c:\\Users\\AndrÃ¨s DLR\\AppData\\Local\\Programs\\Python\\Python310\\lib\\site-packages\\scikeras\\wrappers.py\", line 524, in _fit_keras_model\n    hist = self.model_.fit(x=X, y=y, **fit_args)\n  File \"c:\\Users\\AndrÃ¨s DLR\\AppData\\Local\\Programs\\Python\\Python310\\lib\\site-packages\\keras\\src\\utils\\traceback_utils.py\", line 70, in error_handler\n    raise e.with_traceback(filtered_tb) from None\n  File \"C:\\Users\\ANDRSD~1\\AppData\\Local\\Temp\\__autograph_generated_filethx4_r06.py\", line 15, in tf__train_function\n    retval_ = ag__.converted_call(ag__.ld(step_function), (ag__.ld(self), ag__.ld(iterator)), None, fscope)\nValueError: in user code:\n\n    File \"c:\\Users\\AndrÃ¨s DLR\\AppData\\Local\\Programs\\Python\\Python310\\lib\\site-packages\\keras\\src\\engine\\training.py\", line 1338, in train_function  *\n        return step_function(self, iterator)\n    File \"c:\\Users\\AndrÃ¨s DLR\\AppData\\Local\\Programs\\Python\\Python310\\lib\\site-packages\\keras\\src\\engine\\training.py\", line 1322, in step_function  **\n        outputs = model.distribute_strategy.run(run_step, args=(data,))\n    File \"c:\\Users\\AndrÃ¨s DLR\\AppData\\Local\\Programs\\Python\\Python310\\lib\\site-packages\\keras\\src\\engine\\training.py\", line 1303, in run_step  **\n        outputs = model.train_step(data)\n    File \"c:\\Users\\AndrÃ¨s DLR\\AppData\\Local\\Programs\\Python\\Python310\\lib\\site-packages\\keras\\src\\engine\\training.py\", line 1080, in train_step\n        y_pred = self(x, training=True)\n    File \"c:\\Users\\AndrÃ¨s DLR\\AppData\\Local\\Programs\\Python\\Python310\\lib\\site-packages\\keras\\src\\utils\\traceback_utils.py\", line 70, in error_handler\n        raise e.with_traceback(filtered_tb) from None\n    File \"c:\\Users\\AndrÃ¨s DLR\\AppData\\Local\\Programs\\Python\\Python310\\lib\\site-packages\\keras\\src\\engine\\input_spec.py\", line 298, in assert_input_compatibility\n        raise ValueError(\n\n    ValueError: Input 0 of layer \"sequential_101\" is incompatible with the layer: expected shape=(None, 8), found shape=(10, 5)\n\n\n--------------------------------------------------------------------------------\n1 fits failed with the following error:\nTraceback (most recent call last):\n  File \"c:\\Users\\AndrÃ¨s DLR\\AppData\\Local\\Programs\\Python\\Python310\\lib\\site-packages\\sklearn\\model_selection\\_validation.py\", line 686, in _fit_and_score\n    estimator.fit(X_train, y_train, **fit_params)\n  File \"c:\\Users\\AndrÃ¨s DLR\\AppData\\Local\\Programs\\Python\\Python310\\lib\\site-packages\\scikeras\\wrappers.py\", line 1491, in fit\n    super().fit(X=X, y=y, sample_weight=sample_weight, **kwargs)\n  File \"c:\\Users\\AndrÃ¨s DLR\\AppData\\Local\\Programs\\Python\\Python310\\lib\\site-packages\\scikeras\\wrappers.py\", line 760, in fit\n    self._fit(\n  File \"c:\\Users\\AndrÃ¨s DLR\\AppData\\Local\\Programs\\Python\\Python310\\lib\\site-packages\\scikeras\\wrappers.py\", line 928, in _fit\n    self._fit_keras_model(\n  File \"c:\\Users\\AndrÃ¨s DLR\\AppData\\Local\\Programs\\Python\\Python310\\lib\\site-packages\\scikeras\\wrappers.py\", line 524, in _fit_keras_model\n    hist = self.model_.fit(x=X, y=y, **fit_args)\n  File \"c:\\Users\\AndrÃ¨s DLR\\AppData\\Local\\Programs\\Python\\Python310\\lib\\site-packages\\keras\\src\\utils\\traceback_utils.py\", line 70, in error_handler\n    raise e.with_traceback(filtered_tb) from None\n  File \"C:\\Users\\ANDRSD~1\\AppData\\Local\\Temp\\__autograph_generated_filethx4_r06.py\", line 15, in tf__train_function\n    retval_ = ag__.converted_call(ag__.ld(step_function), (ag__.ld(self), ag__.ld(iterator)), None, fscope)\nValueError: in user code:\n\n    File \"c:\\Users\\AndrÃ¨s DLR\\AppData\\Local\\Programs\\Python\\Python310\\lib\\site-packages\\keras\\src\\engine\\training.py\", line 1338, in train_function  *\n        return step_function(self, iterator)\n    File \"c:\\Users\\AndrÃ¨s DLR\\AppData\\Local\\Programs\\Python\\Python310\\lib\\site-packages\\keras\\src\\engine\\training.py\", line 1322, in step_function  **\n        outputs = model.distribute_strategy.run(run_step, args=(data,))\n    File \"c:\\Users\\AndrÃ¨s DLR\\AppData\\Local\\Programs\\Python\\Python310\\lib\\site-packages\\keras\\src\\engine\\training.py\", line 1303, in run_step  **\n        outputs = model.train_step(data)\n    File \"c:\\Users\\AndrÃ¨s DLR\\AppData\\Local\\Programs\\Python\\Python310\\lib\\site-packages\\keras\\src\\engine\\training.py\", line 1080, in train_step\n        y_pred = self(x, training=True)\n    File \"c:\\Users\\AndrÃ¨s DLR\\AppData\\Local\\Programs\\Python\\Python310\\lib\\site-packages\\keras\\src\\utils\\traceback_utils.py\", line 70, in error_handler\n        raise e.with_traceback(filtered_tb) from None\n    File \"c:\\Users\\AndrÃ¨s DLR\\AppData\\Local\\Programs\\Python\\Python310\\lib\\site-packages\\keras\\src\\engine\\input_spec.py\", line 298, in assert_input_compatibility\n        raise ValueError(\n\n    ValueError: Input 0 of layer \"sequential_102\" is incompatible with the layer: expected shape=(None, 8), found shape=(10, 5)\n\n\n--------------------------------------------------------------------------------\n1 fits failed with the following error:\nTraceback (most recent call last):\n  File \"c:\\Users\\AndrÃ¨s DLR\\AppData\\Local\\Programs\\Python\\Python310\\lib\\site-packages\\sklearn\\model_selection\\_validation.py\", line 686, in _fit_and_score\n    estimator.fit(X_train, y_train, **fit_params)\n  File \"c:\\Users\\AndrÃ¨s DLR\\AppData\\Local\\Programs\\Python\\Python310\\lib\\site-packages\\scikeras\\wrappers.py\", line 1491, in fit\n    super().fit(X=X, y=y, sample_weight=sample_weight, **kwargs)\n  File \"c:\\Users\\AndrÃ¨s DLR\\AppData\\Local\\Programs\\Python\\Python310\\lib\\site-packages\\scikeras\\wrappers.py\", line 760, in fit\n    self._fit(\n  File \"c:\\Users\\AndrÃ¨s DLR\\AppData\\Local\\Programs\\Python\\Python310\\lib\\site-packages\\scikeras\\wrappers.py\", line 928, in _fit\n    self._fit_keras_model(\n  File \"c:\\Users\\AndrÃ¨s DLR\\AppData\\Local\\Programs\\Python\\Python310\\lib\\site-packages\\scikeras\\wrappers.py\", line 524, in _fit_keras_model\n    hist = self.model_.fit(x=X, y=y, **fit_args)\n  File \"c:\\Users\\AndrÃ¨s DLR\\AppData\\Local\\Programs\\Python\\Python310\\lib\\site-packages\\keras\\src\\utils\\traceback_utils.py\", line 70, in error_handler\n    raise e.with_traceback(filtered_tb) from None\n  File \"C:\\Users\\ANDRSD~1\\AppData\\Local\\Temp\\__autograph_generated_filethx4_r06.py\", line 15, in tf__train_function\n    retval_ = ag__.converted_call(ag__.ld(step_function), (ag__.ld(self), ag__.ld(iterator)), None, fscope)\nValueError: in user code:\n\n    File \"c:\\Users\\AndrÃ¨s DLR\\AppData\\Local\\Programs\\Python\\Python310\\lib\\site-packages\\keras\\src\\engine\\training.py\", line 1338, in train_function  *\n        return step_function(self, iterator)\n    File \"c:\\Users\\AndrÃ¨s DLR\\AppData\\Local\\Programs\\Python\\Python310\\lib\\site-packages\\keras\\src\\engine\\training.py\", line 1322, in step_function  **\n        outputs = model.distribute_strategy.run(run_step, args=(data,))\n    File \"c:\\Users\\AndrÃ¨s DLR\\AppData\\Local\\Programs\\Python\\Python310\\lib\\site-packages\\keras\\src\\engine\\training.py\", line 1303, in run_step  **\n        outputs = model.train_step(data)\n    File \"c:\\Users\\AndrÃ¨s DLR\\AppData\\Local\\Programs\\Python\\Python310\\lib\\site-packages\\keras\\src\\engine\\training.py\", line 1080, in train_step\n        y_pred = self(x, training=True)\n    File \"c:\\Users\\AndrÃ¨s DLR\\AppData\\Local\\Programs\\Python\\Python310\\lib\\site-packages\\keras\\src\\utils\\traceback_utils.py\", line 70, in error_handler\n        raise e.with_traceback(filtered_tb) from None\n    File \"c:\\Users\\AndrÃ¨s DLR\\AppData\\Local\\Programs\\Python\\Python310\\lib\\site-packages\\keras\\src\\engine\\input_spec.py\", line 298, in assert_input_compatibility\n        raise ValueError(\n\n    ValueError: Input 0 of layer \"sequential_103\" is incompatible with the layer: expected shape=(None, 8), found shape=(10, 5)\n\n"
     ]
    }
   ],
   "source": [
    "grid = GridSearchCV(estimator=model, param_grid=param_grid, n_jobs=1, cv=3)\n",
    "grid_result = grid.fit(X, Y)\n",
    "# summarize results\n",
    "print(\"Best: %f using %s\" % (grid_result.best_score_, grid_result.best_params_))\n",
    "means = grid_result.cv_results_['mean_test_score']\n",
    "stds = grid_result.cv_results_['std_test_score']\n",
    "params = grid_result.cv_results_['params']\n",
    "for mean, stdev, param in zip(means, stds, params):\n",
    "    print(\"%f (%f) with: %r\" % (mean, stdev, param))"
   ]
  },
  {
   "cell_type": "markdown",
   "metadata": {},
   "source": [
    "## Learning Rate Opt."
   ]
  },
  {
   "cell_type": "code",
   "execution_count": null,
   "metadata": {},
   "outputs": [],
   "source": [
    "\n",
    "def create_model():\n",
    " # create model\n",
    " model = Sequential()\n",
    " model.add(Dense(12, input_shape=(5,), activation='relu'))\n",
    " model.add(Dense(1, activation='sigmoid'))\n",
    " return model"
   ]
  },
  {
   "cell_type": "code",
   "execution_count": null,
   "metadata": {},
   "outputs": [],
   "source": [
    "# fix random seed for reproducibility\n",
    "seed = 7\n",
    "tf.random.set_seed(seed)\n",
    "\n",
    "# create model\n",
    "model = KerasClassifier(model=create_model, loss=\"binary_crossentropy\", optimizer=\"SGD\", epochs=100, batch_size=10, verbose=0)\n",
    "# define the grid search parameters\n",
    "learn_rate = [0.001, 0.01, 0.1]\n",
    "momentum = [0.2, 0.4, 0.6]\n",
    "param_grid = dict(optimizer__learning_rate=learn_rate, optimizer__momentum=momentum)"
   ]
  },
  {
   "cell_type": "code",
   "execution_count": null,
   "metadata": {},
   "outputs": [],
   "source": [
    "grid = GridSearchCV(estimator=model, param_grid=param_grid, n_jobs=1, cv=3)\n",
    "grid_result = grid.fit(X, Y)\n",
    "# summarize results\n",
    "print(\"Best: %f using %s\" % (grid_result.best_score_, grid_result.best_params_))\n",
    "means = grid_result.cv_results_['mean_test_score']\n",
    "stds = grid_result.cv_results_['std_test_score']\n",
    "params = grid_result.cv_results_['params']\n",
    "for mean, stdev, param in zip(means, stds, params):\n",
    "    print(\"%f (%f) with: %r\" % (mean, stdev, param))"
   ]
  },
  {
   "cell_type": "markdown",
   "metadata": {},
   "source": [
    "## Activation Function Opt."
   ]
  },
  {
   "cell_type": "code",
   "execution_count": null,
   "metadata": {},
   "outputs": [],
   "source": [
    "def create_model(activation='relu'):\n",
    " # create model\n",
    " model = Sequential()\n",
    " model.add(Dense(12, input_shape=(5,), kernel_initializer='uniform', activation=activation))\n",
    " model.add(Dense(1, kernel_initializer='uniform', activation='sigmoid'))\n",
    " # Compile model\n",
    " model.compile(loss='binary_crossentropy', optimizer='adam', metrics=['accuracy'])\n",
    " return model\n"
   ]
  },
  {
   "cell_type": "code",
   "execution_count": null,
   "metadata": {},
   "outputs": [],
   "source": [
    "# fix random seed for reproducibility\n",
    "seed = 7\n",
    "tf.random.set_seed(seed)\n",
    "\n",
    "# create model\n",
    "model = KerasClassifier(model=create_model, epochs=100, batch_size=10, verbose=0)\n",
    "# define the grid search parameters\n",
    "activation = ['softmax', 'softplus', 'softsign', 'relu', 'tanh', 'sigmoid', 'hard_sigmoid', 'linear']\n",
    "param_grid = dict(model__activation=activation)"
   ]
  },
  {
   "cell_type": "code",
   "execution_count": null,
   "metadata": {},
   "outputs": [],
   "source": [
    "grid = GridSearchCV(estimator=model, param_grid=param_grid, n_jobs=1, cv=3)\n",
    "grid_result = grid.fit(X, Y)\n",
    "# summarize results\n",
    "print(\"Best: %f using %s\" % (grid_result.best_score_, grid_result.best_params_))\n",
    "means = grid_result.cv_results_['mean_test_score']\n",
    "stds = grid_result.cv_results_['std_test_score']\n",
    "params = grid_result.cv_results_['params']\n",
    "for mean, stdev, param in zip(means, stds, params):\n",
    "    print(\"%f (%f) with: %r\" % (mean, stdev, param))"
   ]
  },
  {
   "cell_type": "markdown",
   "metadata": {},
   "source": [
    "## Number of neurons"
   ]
  },
  {
   "cell_type": "code",
   "execution_count": null,
   "metadata": {},
   "outputs": [],
   "source": [
    "def create_model(neurons):\n",
    " # create model\n",
    " model = Sequential()\n",
    " model.add(Dense(neurons, input_shape=(5,), kernel_initializer='uniform', activation='linear', kernel_constraint=MaxNorm(4)))\n",
    " #model.add(Dropout(0.2))\n",
    " model.add(Dense(1, kernel_initializer='uniform', activation='sigmoid'))\n",
    " # Compile model\n",
    " model.compile(loss='binary_crossentropy', optimizer='adam', metrics=['accuracy'])\n",
    " return model"
   ]
  },
  {
   "cell_type": "code",
   "execution_count": null,
   "metadata": {},
   "outputs": [],
   "source": [
    "# fix random seed for reproducibility\n",
    "seed = 7\n",
    "tf.random.set_seed(seed)\n",
    "\n",
    "# create model\n",
    "model = KerasClassifier(model=create_model, epochs=100, batch_size=10, verbose=0)\n",
    "# define the grid search parameters\n",
    "neurons = [1, 5, 10, 15, 20, 25, 30]\n",
    "param_grid = dict(model__neurons=neurons)\n"
   ]
  },
  {
   "cell_type": "code",
   "execution_count": null,
   "metadata": {},
   "outputs": [],
   "source": [
    "grid = GridSearchCV(estimator=model, param_grid=param_grid, n_jobs=1, cv=3)\n",
    "grid_result = grid.fit(X, Y)\n",
    "# summarize results\n",
    "print(\"Best: %f using %s\" % (grid_result.best_score_, grid_result.best_params_))\n",
    "means = grid_result.cv_results_['mean_test_score']\n",
    "stds = grid_result.cv_results_['std_test_score']\n",
    "params = grid_result.cv_results_['params']\n",
    "for mean, stdev, param in zip(means, stds, params):\n",
    "    print(\"%f (%f) with: %r\" % (mean, stdev, param))"
   ]
  }
 ],
 "metadata": {
  "kernelspec": {
   "display_name": "Python 3",
   "language": "python",
   "name": "python3"
  },
  "language_info": {
   "codemirror_mode": {
    "name": "ipython",
    "version": 3
   },
   "file_extension": ".py",
   "mimetype": "text/x-python",
   "name": "python",
   "nbconvert_exporter": "python",
   "pygments_lexer": "ipython3",
   "version": "3.10.5"
  },
  "orig_nbformat": 4
 },
 "nbformat": 4,
 "nbformat_minor": 2
}
